[2025-02-27T11:08:12.308+0000] {taskinstance.py:1159} INFO - Dependencies all met for dep_context=non-requeueable deps ti=<TaskInstance: fetch_crypto_data_and_upload_to_hdfs.upload_to_hdfs manual__2025-02-27T11:08:04.142888+00:00 [queued]>
[2025-02-27T11:08:12.321+0000] {taskinstance.py:1159} INFO - Dependencies all met for dep_context=requeueable deps ti=<TaskInstance: fetch_crypto_data_and_upload_to_hdfs.upload_to_hdfs manual__2025-02-27T11:08:04.142888+00:00 [queued]>
[2025-02-27T11:08:12.322+0000] {taskinstance.py:1361} INFO - Starting attempt 1 of 2
[2025-02-27T11:08:12.340+0000] {taskinstance.py:1382} INFO - Executing <Task(PythonOperator): upload_to_hdfs> on 2025-02-27 11:08:04.142888+00:00
[2025-02-27T11:08:12.350+0000] {standard_task_runner.py:57} INFO - Started process 522 to run task
[2025-02-27T11:08:12.354+0000] {standard_task_runner.py:84} INFO - Running: ['***', 'tasks', 'run', 'fetch_crypto_data_and_upload_to_hdfs', 'upload_to_hdfs', 'manual__2025-02-27T11:08:04.142888+00:00', '--job-id', '54', '--raw', '--subdir', 'DAGS_FOLDER/ingest_data.py', '--cfg-path', '/tmp/tmpi_z9mrp6']
[2025-02-27T11:08:12.358+0000] {standard_task_runner.py:85} INFO - Job 54: Subtask upload_to_hdfs
[2025-02-27T11:08:12.412+0000] {task_command.py:415} INFO - Running <TaskInstance: fetch_crypto_data_and_upload_to_hdfs.upload_to_hdfs manual__2025-02-27T11:08:04.142888+00:00 [running]> on host bd8db0b15e85
[2025-02-27T11:08:12.502+0000] {taskinstance.py:1660} INFO - Exporting env vars: AIRFLOW_CTX_DAG_OWNER='***' AIRFLOW_CTX_DAG_ID='fetch_crypto_data_and_upload_to_hdfs' AIRFLOW_CTX_TASK_ID='upload_to_hdfs' AIRFLOW_CTX_EXECUTION_DATE='2025-02-27T11:08:04.142888+00:00' AIRFLOW_CTX_TRY_NUMBER='1' AIRFLOW_CTX_DAG_RUN_ID='manual__2025-02-27T11:08:04.142888+00:00'
[2025-02-27T11:08:12.518+0000] {taskinstance.py:1943} ERROR - Task failed with exception
Traceback (most recent call last):
  File "/home/airflow/.local/lib/python3.9/site-packages/airflow/operators/python.py", line 192, in execute
    return_value = self.execute_callable()
  File "/home/airflow/.local/lib/python3.9/site-packages/airflow/operators/python.py", line 209, in execute_callable
    return self.python_callable(*self.op_args, **self.op_kwargs)
  File "/opt/airflow/dags/ingest_data.py", line 58, in upload_to_hdfs
    raise Exception(f"Command failed: {bash_command}\nError: {result.stderr}")
Exception: Command failed: doc&&docker exec namenode bash -c "hdfs dfs -mkdir -p /user/root/crypto/YYYY=2025/MM=02/DD=27 && hdfs dfs -put -f /tmp/crypto_historical_data.csv /user/root/crypto/YYYY=2025/MM=02/DD=27/crypto_historical_data.csv"
Error: /bin/sh: 1: doc: Permission denied

[2025-02-27T11:08:12.541+0000] {taskinstance.py:1400} INFO - Marking task as UP_FOR_RETRY. dag_id=fetch_crypto_data_and_upload_to_hdfs, task_id=upload_to_hdfs, execution_date=20250227T110804, start_date=20250227T110812, end_date=20250227T110812
[2025-02-27T11:08:12.560+0000] {standard_task_runner.py:104} ERROR - Failed to execute job 54 for task upload_to_hdfs (Command failed: doc&&docker exec namenode bash -c "hdfs dfs -mkdir -p /user/root/crypto/YYYY=2025/MM=02/DD=27 && hdfs dfs -put -f /tmp/crypto_historical_data.csv /user/root/crypto/YYYY=2025/MM=02/DD=27/crypto_historical_data.csv"
Error: /bin/sh: 1: doc: Permission denied
; 522)
[2025-02-27T11:08:12.611+0000] {local_task_job_runner.py:228} INFO - Task exited with return code 1
[2025-02-27T11:08:12.644+0000] {taskinstance.py:2784} INFO - 0 downstream tasks scheduled from follow-on schedule check
