[2025-02-22T19:37:55.989+0000] {taskinstance.py:1157} INFO - Dependencies all met for dep_context=non-requeueable deps ti=<TaskInstance: coingecko_ingestion_dag.store_raw_data_in_hdfs scheduled__2025-02-13T00:00:00+00:00 [queued]>
[2025-02-22T19:37:56.084+0000] {taskinstance.py:1157} INFO - Dependencies all met for dep_context=requeueable deps ti=<TaskInstance: coingecko_ingestion_dag.store_raw_data_in_hdfs scheduled__2025-02-13T00:00:00+00:00 [queued]>
[2025-02-22T19:37:56.092+0000] {taskinstance.py:1359} INFO - Starting attempt 2 of 2
[2025-02-22T19:37:56.236+0000] {taskinstance.py:1380} INFO - Executing <Task(PythonOperator): store_raw_data_in_hdfs> on 2025-02-13 00:00:00+00:00
[2025-02-22T19:37:56.281+0000] {standard_task_runner.py:57} INFO - Started process 1490 to run task
[2025-02-22T19:37:56.321+0000] {standard_task_runner.py:84} INFO - Running: ['***', 'tasks', 'run', 'coingecko_ingestion_dag', 'store_raw_data_in_hdfs', 'scheduled__2025-02-13T00:00:00+00:00', '--job-id', '168', '--raw', '--subdir', 'DAGS_FOLDER/ingest_data.py', '--cfg-path', '/tmp/tmpqg2zxu9x']
[2025-02-22T19:37:56.342+0000] {standard_task_runner.py:85} INFO - Job 168: Subtask store_raw_data_in_hdfs
[2025-02-22T19:37:56.725+0000] {task_command.py:415} INFO - Running <TaskInstance: coingecko_ingestion_dag.store_raw_data_in_hdfs scheduled__2025-02-13T00:00:00+00:00 [running]> on host 972836975d47
[2025-02-22T19:37:57.199+0000] {taskinstance.py:1660} INFO - Exporting env vars: AIRFLOW_CTX_DAG_OWNER='etudiant' AIRFLOW_CTX_DAG_ID='coingecko_ingestion_dag' AIRFLOW_CTX_TASK_ID='store_raw_data_in_hdfs' AIRFLOW_CTX_EXECUTION_DATE='2025-02-13T00:00:00+00:00' AIRFLOW_CTX_TRY_NUMBER='2' AIRFLOW_CTX_DAG_RUN_ID='scheduled__2025-02-13T00:00:00+00:00'
[2025-02-22T19:37:57.278+0000] {taskinstance.py:1935} ERROR - Task failed with exception
Traceback (most recent call last):
  File "/home/airflow/.local/lib/python3.8/site-packages/airflow/operators/python.py", line 192, in execute
    return_value = self.execute_callable()
  File "/home/airflow/.local/lib/python3.8/site-packages/airflow/operators/python.py", line 209, in execute_callable
    return self.python_callable(*self.op_args, **self.op_kwargs)
  File "/opt/airflow/dags/ingest_data.py", line 48, in store_raw_data_in_hdfs
    subprocess.run(["hdfs", "dfs", "-mkdir", "-p", hdfs_dir])
  File "/usr/local/lib/python3.8/subprocess.py", line 493, in run
    with Popen(*popenargs, **kwargs) as process:
  File "/usr/local/lib/python3.8/subprocess.py", line 858, in __init__
    self._execute_child(args, executable, preexec_fn, close_fds,
  File "/usr/local/lib/python3.8/subprocess.py", line 1720, in _execute_child
    raise child_exception_type(errno_num, err_msg, err_filename)
PermissionError: [Errno 13] Permission denied: 'hdfs'
[2025-02-22T19:37:57.325+0000] {taskinstance.py:1398} INFO - Marking task as FAILED. dag_id=coingecko_ingestion_dag, task_id=store_raw_data_in_hdfs, execution_date=20250213T000000, start_date=20250222T193756, end_date=20250222T193757
[2025-02-22T19:37:57.357+0000] {standard_task_runner.py:104} ERROR - Failed to execute job 168 for task store_raw_data_in_hdfs ([Errno 13] Permission denied: 'hdfs'; 1490)
[2025-02-22T19:37:57.393+0000] {local_task_job_runner.py:228} INFO - Task exited with return code 1
[2025-02-22T19:37:57.452+0000] {taskinstance.py:2776} INFO - 0 downstream tasks scheduled from follow-on schedule check
[2025-02-23T13:42:41.490+0000] {taskinstance.py:1157} INFO - Dependencies all met for dep_context=non-requeueable deps ti=<TaskInstance: coingecko_ingestion_dag.store_raw_data_in_hdfs scheduled__2025-02-13T00:00:00+00:00 [queued]>
[2025-02-23T13:42:41.508+0000] {taskinstance.py:1157} INFO - Dependencies all met for dep_context=requeueable deps ti=<TaskInstance: coingecko_ingestion_dag.store_raw_data_in_hdfs scheduled__2025-02-13T00:00:00+00:00 [queued]>
[2025-02-23T13:42:41.509+0000] {taskinstance.py:1359} INFO - Starting attempt 2 of 2
[2025-02-23T13:42:41.528+0000] {taskinstance.py:1380} INFO - Executing <Task(PythonOperator): store_raw_data_in_hdfs> on 2025-02-13 00:00:00+00:00
[2025-02-23T13:42:41.535+0000] {standard_task_runner.py:57} INFO - Started process 1616 to run task
[2025-02-23T13:42:41.539+0000] {standard_task_runner.py:84} INFO - Running: ['***', 'tasks', 'run', 'coingecko_ingestion_dag', 'store_raw_data_in_hdfs', 'scheduled__2025-02-13T00:00:00+00:00', '--job-id', '121', '--raw', '--subdir', 'DAGS_FOLDER/ingest_data.py', '--cfg-path', '/tmp/tmp4kfqxsqq']
[2025-02-23T13:42:41.543+0000] {standard_task_runner.py:85} INFO - Job 121: Subtask store_raw_data_in_hdfs
[2025-02-23T13:42:41.627+0000] {task_command.py:415} INFO - Running <TaskInstance: coingecko_ingestion_dag.store_raw_data_in_hdfs scheduled__2025-02-13T00:00:00+00:00 [running]> on host 49036eb7676e
[2025-02-23T13:42:41.755+0000] {taskinstance.py:1660} INFO - Exporting env vars: AIRFLOW_CTX_DAG_OWNER='etudiant' AIRFLOW_CTX_DAG_ID='coingecko_ingestion_dag' AIRFLOW_CTX_TASK_ID='store_raw_data_in_hdfs' AIRFLOW_CTX_EXECUTION_DATE='2025-02-13T00:00:00+00:00' AIRFLOW_CTX_TRY_NUMBER='2' AIRFLOW_CTX_DAG_RUN_ID='scheduled__2025-02-13T00:00:00+00:00'
[2025-02-23T13:42:41.795+0000] {taskinstance.py:1935} ERROR - Task failed with exception
Traceback (most recent call last):
  File "/home/airflow/.local/lib/python3.8/site-packages/airflow/operators/python.py", line 192, in execute
    return_value = self.execute_callable()
  File "/home/airflow/.local/lib/python3.8/site-packages/airflow/operators/python.py", line 209, in execute_callable
    return self.python_callable(*self.op_args, **self.op_kwargs)
  File "/opt/airflow/dags/ingest_data.py", line 48, in store_raw_data_in_hdfs
    subprocess.run(["hdfs", "dfs", "-mkdir", "-p", hdfs_dir])
  File "/usr/local/lib/python3.8/subprocess.py", line 493, in run
    with Popen(*popenargs, **kwargs) as process:
  File "/usr/local/lib/python3.8/subprocess.py", line 858, in __init__
    self._execute_child(args, executable, preexec_fn, close_fds,
  File "/usr/local/lib/python3.8/subprocess.py", line 1720, in _execute_child
    raise child_exception_type(errno_num, err_msg, err_filename)
PermissionError: [Errno 13] Permission denied: 'hdfs'
[2025-02-23T13:42:41.813+0000] {taskinstance.py:1398} INFO - Marking task as FAILED. dag_id=coingecko_ingestion_dag, task_id=store_raw_data_in_hdfs, execution_date=20250213T000000, start_date=20250223T134241, end_date=20250223T134241
[2025-02-23T13:42:41.833+0000] {standard_task_runner.py:104} ERROR - Failed to execute job 121 for task store_raw_data_in_hdfs ([Errno 13] Permission denied: 'hdfs'; 1616)
[2025-02-23T13:42:41.877+0000] {local_task_job_runner.py:228} INFO - Task exited with return code 1
[2025-02-23T13:42:41.924+0000] {taskinstance.py:2776} INFO - 0 downstream tasks scheduled from follow-on schedule check
