[2025-02-22T19:22:14.178+0000] {taskinstance.py:1157} INFO - Dependencies all met for dep_context=non-requeueable deps ti=<TaskInstance: coingecko_ingestion_dag.store_raw_data_in_hdfs scheduled__2025-01-06T00:00:00+00:00 [queued]>
[2025-02-22T19:22:14.201+0000] {taskinstance.py:1157} INFO - Dependencies all met for dep_context=requeueable deps ti=<TaskInstance: coingecko_ingestion_dag.store_raw_data_in_hdfs scheduled__2025-01-06T00:00:00+00:00 [queued]>
[2025-02-22T19:22:14.202+0000] {taskinstance.py:1359} INFO - Starting attempt 2 of 2
[2025-02-22T19:22:14.235+0000] {taskinstance.py:1380} INFO - Executing <Task(PythonOperator): store_raw_data_in_hdfs> on 2025-01-06 00:00:00+00:00
[2025-02-22T19:22:14.244+0000] {standard_task_runner.py:57} INFO - Started process 1136 to run task
[2025-02-22T19:22:14.253+0000] {standard_task_runner.py:84} INFO - Running: ['***', 'tasks', 'run', 'coingecko_ingestion_dag', 'store_raw_data_in_hdfs', 'scheduled__2025-01-06T00:00:00+00:00', '--job-id', '62', '--raw', '--subdir', 'DAGS_FOLDER/ingest_data.py', '--cfg-path', '/tmp/tmprkd5e32m']
[2025-02-22T19:22:14.259+0000] {standard_task_runner.py:85} INFO - Job 62: Subtask store_raw_data_in_hdfs
[2025-02-22T19:22:14.385+0000] {task_command.py:415} INFO - Running <TaskInstance: coingecko_ingestion_dag.store_raw_data_in_hdfs scheduled__2025-01-06T00:00:00+00:00 [running]> on host 972836975d47
[2025-02-22T19:22:14.535+0000] {taskinstance.py:1660} INFO - Exporting env vars: AIRFLOW_CTX_DAG_OWNER='etudiant' AIRFLOW_CTX_DAG_ID='coingecko_ingestion_dag' AIRFLOW_CTX_TASK_ID='store_raw_data_in_hdfs' AIRFLOW_CTX_EXECUTION_DATE='2025-01-06T00:00:00+00:00' AIRFLOW_CTX_TRY_NUMBER='2' AIRFLOW_CTX_DAG_RUN_ID='scheduled__2025-01-06T00:00:00+00:00'
[2025-02-22T19:22:14.575+0000] {taskinstance.py:1935} ERROR - Task failed with exception
Traceback (most recent call last):
  File "/home/airflow/.local/lib/python3.8/site-packages/airflow/operators/python.py", line 192, in execute
    return_value = self.execute_callable()
  File "/home/airflow/.local/lib/python3.8/site-packages/airflow/operators/python.py", line 209, in execute_callable
    return self.python_callable(*self.op_args, **self.op_kwargs)
  File "/opt/airflow/dags/ingest_data.py", line 48, in store_raw_data_in_hdfs
    subprocess.run(["hdfs", "dfs", "-mkdir", "-p", hdfs_dir])
  File "/usr/local/lib/python3.8/subprocess.py", line 493, in run
    with Popen(*popenargs, **kwargs) as process:
  File "/usr/local/lib/python3.8/subprocess.py", line 858, in __init__
    self._execute_child(args, executable, preexec_fn, close_fds,
  File "/usr/local/lib/python3.8/subprocess.py", line 1720, in _execute_child
    raise child_exception_type(errno_num, err_msg, err_filename)
PermissionError: [Errno 13] Permission denied: 'hdfs'
[2025-02-22T19:22:14.596+0000] {taskinstance.py:1398} INFO - Marking task as FAILED. dag_id=coingecko_ingestion_dag, task_id=store_raw_data_in_hdfs, execution_date=20250106T000000, start_date=20250222T192214, end_date=20250222T192214
[2025-02-22T19:22:14.619+0000] {standard_task_runner.py:104} ERROR - Failed to execute job 62 for task store_raw_data_in_hdfs ([Errno 13] Permission denied: 'hdfs'; 1136)
[2025-02-22T19:22:14.669+0000] {local_task_job_runner.py:228} INFO - Task exited with return code 1
[2025-02-22T19:22:14.695+0000] {taskinstance.py:2776} INFO - 0 downstream tasks scheduled from follow-on schedule check
