[2025-02-25T17:11:56.150+0000] {taskinstance.py:1159} INFO - Dependencies all met for dep_context=non-requeueable deps ti=<TaskInstance: crypto_data_processing_mapreduce.run_mapreduce_job manual__2025-02-25T17:11:50.571494+00:00 [queued]>
[2025-02-25T17:11:56.164+0000] {taskinstance.py:1159} INFO - Dependencies all met for dep_context=requeueable deps ti=<TaskInstance: crypto_data_processing_mapreduce.run_mapreduce_job manual__2025-02-25T17:11:50.571494+00:00 [queued]>
[2025-02-25T17:11:56.165+0000] {taskinstance.py:1361} INFO - Starting attempt 1 of 2
[2025-02-25T17:11:56.184+0000] {taskinstance.py:1382} INFO - Executing <Task(BashOperator): run_mapreduce_job> on 2025-02-25 17:11:50.571494+00:00
[2025-02-25T17:11:56.193+0000] {standard_task_runner.py:57} INFO - Started process 1094 to run task
[2025-02-25T17:11:56.196+0000] {standard_task_runner.py:84} INFO - Running: ['***', 'tasks', 'run', 'crypto_data_processing_mapreduce', 'run_mapreduce_job', 'manual__2025-02-25T17:11:50.571494+00:00', '--job-id', '3', '--raw', '--subdir', 'DAGS_FOLDER/transform_data.py', '--cfg-path', '/tmp/tmpeyn61t4d']
[2025-02-25T17:11:56.200+0000] {standard_task_runner.py:85} INFO - Job 3: Subtask run_mapreduce_job
[2025-02-25T17:11:56.275+0000] {task_command.py:415} INFO - Running <TaskInstance: crypto_data_processing_mapreduce.run_mapreduce_job manual__2025-02-25T17:11:50.571494+00:00 [running]> on host bd2eedaff2f8
[2025-02-25T17:11:56.411+0000] {taskinstance.py:1660} INFO - Exporting env vars: AIRFLOW_CTX_DAG_OWNER='***' AIRFLOW_CTX_DAG_ID='crypto_data_processing_mapreduce' AIRFLOW_CTX_TASK_ID='run_mapreduce_job' AIRFLOW_CTX_EXECUTION_DATE='2025-02-25T17:11:50.571494+00:00' AIRFLOW_CTX_TRY_NUMBER='1' AIRFLOW_CTX_DAG_RUN_ID='manual__2025-02-25T17:11:50.571494+00:00'
[2025-02-25T17:11:56.415+0000] {subprocess.py:63} INFO - Tmp dir root location: /tmp
[2025-02-25T17:11:56.419+0000] {subprocess.py:75} INFO - Running command: ['/bin/bash', '-c', 'docker exec namenode ls']
[2025-02-25T17:11:56.435+0000] {subprocess.py:86} INFO - Output:
[2025-02-25T17:11:56.440+0000] {subprocess.py:93} INFO - /bin/bash: line 1: docker: command not found
[2025-02-25T17:11:56.441+0000] {subprocess.py:97} INFO - Command exited with return code 127
[2025-02-25T17:11:56.458+0000] {taskinstance.py:1943} ERROR - Task failed with exception
Traceback (most recent call last):
  File "/home/airflow/.local/lib/python3.9/site-packages/airflow/operators/bash.py", line 210, in execute
    raise AirflowException(
airflow.exceptions.AirflowException: Bash command failed. The command returned a non-zero exit code 127.
[2025-02-25T17:11:56.463+0000] {taskinstance.py:1400} INFO - Marking task as UP_FOR_RETRY. dag_id=crypto_data_processing_mapreduce, task_id=run_mapreduce_job, execution_date=20250225T171150, start_date=20250225T171156, end_date=20250225T171156
[2025-02-25T17:11:56.484+0000] {standard_task_runner.py:104} ERROR - Failed to execute job 3 for task run_mapreduce_job (Bash command failed. The command returned a non-zero exit code 127.; 1094)
[2025-02-25T17:11:56.531+0000] {local_task_job_runner.py:228} INFO - Task exited with return code 1
[2025-02-25T17:11:56.563+0000] {taskinstance.py:2784} INFO - 0 downstream tasks scheduled from follow-on schedule check
