[2025-02-26T19:53:44.699+0000] {taskinstance.py:1159} INFO - Dependencies all met for dep_context=non-requeueable deps ti=<TaskInstance: load_to_habase.load_into_hbase manual__2025-02-26T19:53:40.087723+00:00 [queued]>
[2025-02-26T19:53:44.718+0000] {taskinstance.py:1159} INFO - Dependencies all met for dep_context=requeueable deps ti=<TaskInstance: load_to_habase.load_into_hbase manual__2025-02-26T19:53:40.087723+00:00 [queued]>
[2025-02-26T19:53:44.719+0000] {taskinstance.py:1361} INFO - Starting attempt 1 of 2
[2025-02-26T19:53:44.748+0000] {taskinstance.py:1382} INFO - Executing <Task(PythonOperator): load_into_hbase> on 2025-02-26 19:53:40.087723+00:00
[2025-02-26T19:53:44.760+0000] {standard_task_runner.py:57} INFO - Started process 12808 to run task
[2025-02-26T19:53:44.789+0000] {standard_task_runner.py:84} INFO - Running: ['***', 'tasks', 'run', 'load_to_habase', 'load_into_hbase', 'manual__2025-02-26T19:53:40.087723+00:00', '--job-id', '27', '--raw', '--subdir', 'DAGS_FOLDER/load_data.py', '--cfg-path', '/tmp/tmpbrzkea0s']
[2025-02-26T19:53:44.806+0000] {standard_task_runner.py:85} INFO - Job 27: Subtask load_into_hbase
[2025-02-26T19:53:45.162+0000] {task_command.py:415} INFO - Running <TaskInstance: load_to_habase.load_into_hbase manual__2025-02-26T19:53:40.087723+00:00 [running]> on host 8d9ab8d4ded3
[2025-02-26T19:53:45.450+0000] {taskinstance.py:1660} INFO - Exporting env vars: AIRFLOW_CTX_DAG_OWNER='***' AIRFLOW_CTX_DAG_ID='load_to_habase' AIRFLOW_CTX_TASK_ID='load_into_hbase' AIRFLOW_CTX_EXECUTION_DATE='2025-02-26T19:53:40.087723+00:00' AIRFLOW_CTX_TRY_NUMBER='1' AIRFLOW_CTX_DAG_RUN_ID='manual__2025-02-26T19:53:40.087723+00:00'
[2025-02-26T19:53:45.474+0000] {taskinstance.py:1943} ERROR - Task failed with exception
Traceback (most recent call last):
  File "/home/airflow/.local/lib/python3.9/site-packages/airflow/operators/python.py", line 192, in execute
    return_value = self.execute_callable()
  File "/home/airflow/.local/lib/python3.9/site-packages/airflow/operators/python.py", line 209, in execute_callable
    return self.python_callable(*self.op_args, **self.op_kwargs)
  File "/opt/airflow/dags/load_data.py", line 27, in load_processed_data
    result = subprocess.run(
  File "/usr/local/lib/python3.9/subprocess.py", line 505, in run
    with Popen(*popenargs, **kwargs) as process:
  File "/usr/local/lib/python3.9/subprocess.py", line 951, in __init__
    self._execute_child(args, executable, preexec_fn, close_fds,
  File "/usr/local/lib/python3.9/subprocess.py", line 1837, in _execute_child
    raise child_exception_type(errno_num, err_msg, err_filename)
PermissionError: [Errno 13] Permission denied: 'hdfs'
[2025-02-26T19:53:45.512+0000] {taskinstance.py:1400} INFO - Marking task as UP_FOR_RETRY. dag_id=load_to_habase, task_id=load_into_hbase, execution_date=20250226T195340, start_date=20250226T195344, end_date=20250226T195345
[2025-02-26T19:53:45.560+0000] {standard_task_runner.py:104} ERROR - Failed to execute job 27 for task load_into_hbase ([Errno 13] Permission denied: 'hdfs'; 12808)
[2025-02-26T19:53:45.601+0000] {local_task_job_runner.py:228} INFO - Task exited with return code 1
[2025-02-26T19:53:45.665+0000] {taskinstance.py:2784} INFO - 0 downstream tasks scheduled from follow-on schedule check
