[2025-02-22T18:47:15.354+0000] {taskinstance.py:1157} INFO - Dependencies all met for dep_context=non-requeueable deps ti=<TaskInstance: new_dag_1.check_file scheduled__2025-02-21T00:00:00+00:00 [queued]>
[2025-02-22T18:47:15.365+0000] {taskinstance.py:1157} INFO - Dependencies all met for dep_context=requeueable deps ti=<TaskInstance: new_dag_1.check_file scheduled__2025-02-21T00:00:00+00:00 [queued]>
[2025-02-22T18:47:15.366+0000] {taskinstance.py:1359} INFO - Starting attempt 3 of 6
[2025-02-22T18:47:15.383+0000] {taskinstance.py:1380} INFO - Executing <Task(BashOperator): check_file> on 2025-02-21 00:00:00+00:00
[2025-02-22T18:47:15.389+0000] {standard_task_runner.py:57} INFO - Started process 390 to run task
[2025-02-22T18:47:15.394+0000] {standard_task_runner.py:84} INFO - Running: ['***', 'tasks', 'run', 'new_dag_1', 'check_file', 'scheduled__2025-02-21T00:00:00+00:00', '--job-id', '14', '--raw', '--subdir', 'DAGS_FOLDER/ingest_data.py', '--cfg-path', '/tmp/tmpf6k9oxxh']
[2025-02-22T18:47:15.397+0000] {standard_task_runner.py:85} INFO - Job 14: Subtask check_file
[2025-02-22T18:47:15.463+0000] {task_command.py:415} INFO - Running <TaskInstance: new_dag_1.check_file scheduled__2025-02-21T00:00:00+00:00 [running]> on host 972836975d47
[2025-02-22T18:47:15.568+0000] {taskinstance.py:1660} INFO - Exporting env vars: AIRFLOW_CTX_DAG_OWNER='***' AIRFLOW_CTX_DAG_ID='new_dag_1' AIRFLOW_CTX_TASK_ID='check_file' AIRFLOW_CTX_EXECUTION_DATE='2025-02-21T00:00:00+00:00' AIRFLOW_CTX_TRY_NUMBER='3' AIRFLOW_CTX_DAG_RUN_ID='scheduled__2025-02-21T00:00:00+00:00'
[2025-02-22T18:47:15.571+0000] {subprocess.py:63} INFO - Tmp dir root location: /tmp
[2025-02-22T18:47:15.573+0000] {subprocess.py:75} INFO - Running command: ['/bin/bash', '-c', 'ls -l /mnt/d/projets/***/input/persons.csv']
[2025-02-22T18:47:15.585+0000] {subprocess.py:86} INFO - Output:
[2025-02-22T18:47:15.589+0000] {subprocess.py:93} INFO - ls: cannot access '/mnt/d/projets/***/input/persons.csv': No such file or directory
[2025-02-22T18:47:15.590+0000] {subprocess.py:97} INFO - Command exited with return code 2
[2025-02-22T18:47:15.602+0000] {taskinstance.py:1935} ERROR - Task failed with exception
Traceback (most recent call last):
  File "/home/airflow/.local/lib/python3.8/site-packages/airflow/operators/bash.py", line 210, in execute
    raise AirflowException(
airflow.exceptions.AirflowException: Bash command failed. The command returned a non-zero exit code 2.
[2025-02-22T18:47:15.611+0000] {taskinstance.py:1398} INFO - Marking task as UP_FOR_RETRY. dag_id=new_dag_1, task_id=check_file, execution_date=20250221T000000, start_date=20250222T184715, end_date=20250222T184715
[2025-02-22T18:47:15.630+0000] {standard_task_runner.py:104} ERROR - Failed to execute job 14 for task check_file (Bash command failed. The command returned a non-zero exit code 2.; 390)
[2025-02-22T18:47:15.651+0000] {local_task_job_runner.py:228} INFO - Task exited with return code 1
[2025-02-22T18:47:15.672+0000] {taskinstance.py:2776} INFO - 0 downstream tasks scheduled from follow-on schedule check
