[2025-02-22T19:37:55.575+0000] {taskinstance.py:1157} INFO - Dependencies all met for dep_context=non-requeueable deps ti=<TaskInstance: coingecko_ingestion_dag.store_raw_data_in_hdfs scheduled__2025-02-15T00:00:00+00:00 [queued]>
[2025-02-22T19:37:55.722+0000] {taskinstance.py:1157} INFO - Dependencies all met for dep_context=requeueable deps ti=<TaskInstance: coingecko_ingestion_dag.store_raw_data_in_hdfs scheduled__2025-02-15T00:00:00+00:00 [queued]>
[2025-02-22T19:37:55.730+0000] {taskinstance.py:1359} INFO - Starting attempt 2 of 2
[2025-02-22T19:37:56.502+0000] {taskinstance.py:1380} INFO - Executing <Task(PythonOperator): store_raw_data_in_hdfs> on 2025-02-15 00:00:00+00:00
[2025-02-22T19:37:56.562+0000] {standard_task_runner.py:57} INFO - Started process 1496 to run task
[2025-02-22T19:37:56.574+0000] {standard_task_runner.py:84} INFO - Running: ['***', 'tasks', 'run', 'coingecko_ingestion_dag', 'store_raw_data_in_hdfs', 'scheduled__2025-02-15T00:00:00+00:00', '--job-id', '163', '--raw', '--subdir', 'DAGS_FOLDER/ingest_data.py', '--cfg-path', '/tmp/tmprmuzkp7v']
[2025-02-22T19:37:56.606+0000] {standard_task_runner.py:85} INFO - Job 163: Subtask store_raw_data_in_hdfs
[2025-02-22T19:37:57.025+0000] {task_command.py:415} INFO - Running <TaskInstance: coingecko_ingestion_dag.store_raw_data_in_hdfs scheduled__2025-02-15T00:00:00+00:00 [running]> on host 972836975d47
[2025-02-22T19:37:57.403+0000] {taskinstance.py:1660} INFO - Exporting env vars: AIRFLOW_CTX_DAG_OWNER='etudiant' AIRFLOW_CTX_DAG_ID='coingecko_ingestion_dag' AIRFLOW_CTX_TASK_ID='store_raw_data_in_hdfs' AIRFLOW_CTX_EXECUTION_DATE='2025-02-15T00:00:00+00:00' AIRFLOW_CTX_TRY_NUMBER='2' AIRFLOW_CTX_DAG_RUN_ID='scheduled__2025-02-15T00:00:00+00:00'
[2025-02-22T19:37:57.500+0000] {taskinstance.py:1935} ERROR - Task failed with exception
Traceback (most recent call last):
  File "/home/airflow/.local/lib/python3.8/site-packages/airflow/operators/python.py", line 192, in execute
    return_value = self.execute_callable()
  File "/home/airflow/.local/lib/python3.8/site-packages/airflow/operators/python.py", line 209, in execute_callable
    return self.python_callable(*self.op_args, **self.op_kwargs)
  File "/opt/airflow/dags/ingest_data.py", line 48, in store_raw_data_in_hdfs
    subprocess.run(["hdfs", "dfs", "-mkdir", "-p", hdfs_dir])
  File "/usr/local/lib/python3.8/subprocess.py", line 493, in run
    with Popen(*popenargs, **kwargs) as process:
  File "/usr/local/lib/python3.8/subprocess.py", line 858, in __init__
    self._execute_child(args, executable, preexec_fn, close_fds,
  File "/usr/local/lib/python3.8/subprocess.py", line 1720, in _execute_child
    raise child_exception_type(errno_num, err_msg, err_filename)
PermissionError: [Errno 13] Permission denied: 'hdfs'
[2025-02-22T19:37:57.563+0000] {taskinstance.py:1398} INFO - Marking task as FAILED. dag_id=coingecko_ingestion_dag, task_id=store_raw_data_in_hdfs, execution_date=20250215T000000, start_date=20250222T193755, end_date=20250222T193757
[2025-02-22T19:37:57.592+0000] {standard_task_runner.py:104} ERROR - Failed to execute job 163 for task store_raw_data_in_hdfs ([Errno 13] Permission denied: 'hdfs'; 1496)
[2025-02-22T19:37:57.629+0000] {local_task_job_runner.py:228} INFO - Task exited with return code 1
[2025-02-22T19:37:57.919+0000] {taskinstance.py:2776} INFO - 0 downstream tasks scheduled from follow-on schedule check
