[2025-02-22T19:43:07.515+0000] {taskinstance.py:1157} INFO - Dependencies all met for dep_context=non-requeueable deps ti=<TaskInstance: coingecko_ingestion_dag.store_raw_data_in_hdfs scheduled__2025-02-17T00:00:00+00:00 [queued]>
[2025-02-22T19:43:07.540+0000] {taskinstance.py:1157} INFO - Dependencies all met for dep_context=requeueable deps ti=<TaskInstance: coingecko_ingestion_dag.store_raw_data_in_hdfs scheduled__2025-02-17T00:00:00+00:00 [queued]>
[2025-02-22T19:43:07.541+0000] {taskinstance.py:1359} INFO - Starting attempt 2 of 2
[2025-02-22T19:43:07.572+0000] {taskinstance.py:1380} INFO - Executing <Task(PythonOperator): store_raw_data_in_hdfs> on 2025-02-17 00:00:00+00:00
[2025-02-22T19:43:07.585+0000] {standard_task_runner.py:57} INFO - Started process 1593 to run task
[2025-02-22T19:43:07.593+0000] {standard_task_runner.py:84} INFO - Running: ['***', 'tasks', 'run', 'coingecko_ingestion_dag', 'store_raw_data_in_hdfs', 'scheduled__2025-02-17T00:00:00+00:00', '--job-id', '183', '--raw', '--subdir', 'DAGS_FOLDER/ingest_data.py', '--cfg-path', '/tmp/tmpagwz86r_']
[2025-02-22T19:43:07.602+0000] {standard_task_runner.py:85} INFO - Job 183: Subtask store_raw_data_in_hdfs
[2025-02-22T19:43:07.756+0000] {task_command.py:415} INFO - Running <TaskInstance: coingecko_ingestion_dag.store_raw_data_in_hdfs scheduled__2025-02-17T00:00:00+00:00 [running]> on host 972836975d47
[2025-02-22T19:43:07.930+0000] {taskinstance.py:1660} INFO - Exporting env vars: AIRFLOW_CTX_DAG_OWNER='etudiant' AIRFLOW_CTX_DAG_ID='coingecko_ingestion_dag' AIRFLOW_CTX_TASK_ID='store_raw_data_in_hdfs' AIRFLOW_CTX_EXECUTION_DATE='2025-02-17T00:00:00+00:00' AIRFLOW_CTX_TRY_NUMBER='2' AIRFLOW_CTX_DAG_RUN_ID='scheduled__2025-02-17T00:00:00+00:00'
[2025-02-22T19:43:07.984+0000] {taskinstance.py:1935} ERROR - Task failed with exception
Traceback (most recent call last):
  File "/home/airflow/.local/lib/python3.8/site-packages/airflow/operators/python.py", line 192, in execute
    return_value = self.execute_callable()
  File "/home/airflow/.local/lib/python3.8/site-packages/airflow/operators/python.py", line 209, in execute_callable
    return self.python_callable(*self.op_args, **self.op_kwargs)
  File "/opt/airflow/dags/ingest_data.py", line 48, in store_raw_data_in_hdfs
    subprocess.run(["hdfs", "dfs", "-mkdir", "-p", hdfs_dir])
  File "/usr/local/lib/python3.8/subprocess.py", line 493, in run
    with Popen(*popenargs, **kwargs) as process:
  File "/usr/local/lib/python3.8/subprocess.py", line 858, in __init__
    self._execute_child(args, executable, preexec_fn, close_fds,
  File "/usr/local/lib/python3.8/subprocess.py", line 1720, in _execute_child
    raise child_exception_type(errno_num, err_msg, err_filename)
PermissionError: [Errno 13] Permission denied: 'hdfs'
[2025-02-22T19:43:08.011+0000] {taskinstance.py:1398} INFO - Marking task as FAILED. dag_id=coingecko_ingestion_dag, task_id=store_raw_data_in_hdfs, execution_date=20250217T000000, start_date=20250222T194307, end_date=20250222T194308
[2025-02-22T19:43:08.046+0000] {standard_task_runner.py:104} ERROR - Failed to execute job 183 for task store_raw_data_in_hdfs ([Errno 13] Permission denied: 'hdfs'; 1593)
[2025-02-22T19:43:08.089+0000] {local_task_job_runner.py:228} INFO - Task exited with return code 1
[2025-02-22T19:43:08.126+0000] {taskinstance.py:2776} INFO - 0 downstream tasks scheduled from follow-on schedule check
[2025-02-23T13:42:43.537+0000] {taskinstance.py:1157} INFO - Dependencies all met for dep_context=non-requeueable deps ti=<TaskInstance: coingecko_ingestion_dag.store_raw_data_in_hdfs scheduled__2025-02-17T00:00:00+00:00 [queued]>
[2025-02-23T13:42:43.548+0000] {taskinstance.py:1157} INFO - Dependencies all met for dep_context=requeueable deps ti=<TaskInstance: coingecko_ingestion_dag.store_raw_data_in_hdfs scheduled__2025-02-17T00:00:00+00:00 [queued]>
[2025-02-23T13:42:43.548+0000] {taskinstance.py:1359} INFO - Starting attempt 2 of 2
[2025-02-23T13:42:43.562+0000] {taskinstance.py:1380} INFO - Executing <Task(PythonOperator): store_raw_data_in_hdfs> on 2025-02-17 00:00:00+00:00
[2025-02-23T13:42:43.569+0000] {standard_task_runner.py:57} INFO - Started process 1622 to run task
[2025-02-23T13:42:43.572+0000] {standard_task_runner.py:84} INFO - Running: ['***', 'tasks', 'run', 'coingecko_ingestion_dag', 'store_raw_data_in_hdfs', 'scheduled__2025-02-17T00:00:00+00:00', '--job-id', '124', '--raw', '--subdir', 'DAGS_FOLDER/ingest_data.py', '--cfg-path', '/tmp/tmpg5240v6t']
[2025-02-23T13:42:43.575+0000] {standard_task_runner.py:85} INFO - Job 124: Subtask store_raw_data_in_hdfs
[2025-02-23T13:42:43.627+0000] {task_command.py:415} INFO - Running <TaskInstance: coingecko_ingestion_dag.store_raw_data_in_hdfs scheduled__2025-02-17T00:00:00+00:00 [running]> on host 49036eb7676e
[2025-02-23T13:42:43.706+0000] {taskinstance.py:1660} INFO - Exporting env vars: AIRFLOW_CTX_DAG_OWNER='etudiant' AIRFLOW_CTX_DAG_ID='coingecko_ingestion_dag' AIRFLOW_CTX_TASK_ID='store_raw_data_in_hdfs' AIRFLOW_CTX_EXECUTION_DATE='2025-02-17T00:00:00+00:00' AIRFLOW_CTX_TRY_NUMBER='2' AIRFLOW_CTX_DAG_RUN_ID='scheduled__2025-02-17T00:00:00+00:00'
[2025-02-23T13:42:43.734+0000] {taskinstance.py:1935} ERROR - Task failed with exception
Traceback (most recent call last):
  File "/home/airflow/.local/lib/python3.8/site-packages/airflow/operators/python.py", line 192, in execute
    return_value = self.execute_callable()
  File "/home/airflow/.local/lib/python3.8/site-packages/airflow/operators/python.py", line 209, in execute_callable
    return self.python_callable(*self.op_args, **self.op_kwargs)
  File "/opt/airflow/dags/ingest_data.py", line 48, in store_raw_data_in_hdfs
    subprocess.run(["hdfs", "dfs", "-mkdir", "-p", hdfs_dir])
  File "/usr/local/lib/python3.8/subprocess.py", line 493, in run
    with Popen(*popenargs, **kwargs) as process:
  File "/usr/local/lib/python3.8/subprocess.py", line 858, in __init__
    self._execute_child(args, executable, preexec_fn, close_fds,
  File "/usr/local/lib/python3.8/subprocess.py", line 1720, in _execute_child
    raise child_exception_type(errno_num, err_msg, err_filename)
PermissionError: [Errno 13] Permission denied: 'hdfs'
[2025-02-23T13:42:43.752+0000] {taskinstance.py:1398} INFO - Marking task as FAILED. dag_id=coingecko_ingestion_dag, task_id=store_raw_data_in_hdfs, execution_date=20250217T000000, start_date=20250223T134243, end_date=20250223T134243
[2025-02-23T13:42:43.772+0000] {standard_task_runner.py:104} ERROR - Failed to execute job 124 for task store_raw_data_in_hdfs ([Errno 13] Permission denied: 'hdfs'; 1622)
[2025-02-23T13:42:43.790+0000] {local_task_job_runner.py:228} INFO - Task exited with return code 1
[2025-02-23T13:42:43.810+0000] {taskinstance.py:2776} INFO - 0 downstream tasks scheduled from follow-on schedule check
