[2025-02-25T17:17:45.384+0000] {taskinstance.py:1159} INFO - Dependencies all met for dep_context=non-requeueable deps ti=<TaskInstance: fetch_crypto_data_and_upload_to_hdfs.upload_to_hdfs manual__2025-02-25T17:17:35.121586+00:00 [queued]>
[2025-02-25T17:17:45.417+0000] {taskinstance.py:1159} INFO - Dependencies all met for dep_context=requeueable deps ti=<TaskInstance: fetch_crypto_data_and_upload_to_hdfs.upload_to_hdfs manual__2025-02-25T17:17:35.121586+00:00 [queued]>
[2025-02-25T17:17:45.418+0000] {taskinstance.py:1361} INFO - Starting attempt 1 of 2
[2025-02-25T17:17:45.441+0000] {taskinstance.py:1382} INFO - Executing <Task(PythonOperator): upload_to_hdfs> on 2025-02-25 17:17:35.121586+00:00
[2025-02-25T17:17:45.453+0000] {standard_task_runner.py:57} INFO - Started process 7339 to run task
[2025-02-25T17:17:45.459+0000] {standard_task_runner.py:84} INFO - Running: ['***', 'tasks', 'run', 'fetch_crypto_data_and_upload_to_hdfs', 'upload_to_hdfs', 'manual__2025-02-25T17:17:35.121586+00:00', '--job-id', '8', '--raw', '--subdir', 'DAGS_FOLDER/ingest_data.py', '--cfg-path', '/tmp/tmpw78s4vdf']
[2025-02-25T17:17:45.464+0000] {standard_task_runner.py:85} INFO - Job 8: Subtask upload_to_hdfs
[2025-02-25T17:17:45.543+0000] {task_command.py:415} INFO - Running <TaskInstance: fetch_crypto_data_and_upload_to_hdfs.upload_to_hdfs manual__2025-02-25T17:17:35.121586+00:00 [running]> on host bd2eedaff2f8
[2025-02-25T17:17:45.630+0000] {taskinstance.py:1660} INFO - Exporting env vars: AIRFLOW_CTX_DAG_OWNER='***' AIRFLOW_CTX_DAG_ID='fetch_crypto_data_and_upload_to_hdfs' AIRFLOW_CTX_TASK_ID='upload_to_hdfs' AIRFLOW_CTX_EXECUTION_DATE='2025-02-25T17:17:35.121586+00:00' AIRFLOW_CTX_TRY_NUMBER='1' AIRFLOW_CTX_DAG_RUN_ID='manual__2025-02-25T17:17:35.121586+00:00'
[2025-02-25T17:17:50.820+0000] {taskinstance.py:1943} ERROR - Task failed with exception
Traceback (most recent call last):
  File "/home/airflow/.local/lib/python3.9/site-packages/airflow/operators/python.py", line 192, in execute
    return_value = self.execute_callable()
  File "/home/airflow/.local/lib/python3.9/site-packages/airflow/operators/python.py", line 209, in execute_callable
    return self.python_callable(*self.op_args, **self.op_kwargs)
  File "/opt/airflow/dags/ingest_data.py", line 316, in upload_to_hdfs
    raise Exception(f"Command failed: {bash_command}\nError: {result.stderr}")
Exception: Command failed: docker exec namenode bash -c "hdfs dfs -mkdir -p /user/root/crypto/YYYY=2025/MM=02/DD=25 && hdfs dfs -put -f /tmp/crypto_historical_data.csv /user/root/crypto/YYYY=2025/MM=02/DD=25/crypto_historical_data.csv"
Error: put: `/tmp/crypto_historical_data.csv': No such file or directory

[2025-02-25T17:17:50.841+0000] {taskinstance.py:1400} INFO - Marking task as UP_FOR_RETRY. dag_id=fetch_crypto_data_and_upload_to_hdfs, task_id=upload_to_hdfs, execution_date=20250225T171735, start_date=20250225T171745, end_date=20250225T171750
[2025-02-25T17:17:50.856+0000] {standard_task_runner.py:104} ERROR - Failed to execute job 8 for task upload_to_hdfs (Command failed: docker exec namenode bash -c "hdfs dfs -mkdir -p /user/root/crypto/YYYY=2025/MM=02/DD=25 && hdfs dfs -put -f /tmp/crypto_historical_data.csv /user/root/crypto/YYYY=2025/MM=02/DD=25/crypto_historical_data.csv"
Error: put: `/tmp/crypto_historical_data.csv': No such file or directory
; 7339)
[2025-02-25T17:17:50.868+0000] {local_task_job_runner.py:228} INFO - Task exited with return code 1
[2025-02-25T17:17:50.898+0000] {taskinstance.py:2784} INFO - 0 downstream tasks scheduled from follow-on schedule check
