[2025-02-22T19:38:05.456+0000] {taskinstance.py:1157} INFO - Dependencies all met for dep_context=non-requeueable deps ti=<TaskInstance: coingecko_ingestion_dag.store_raw_data_in_hdfs scheduled__2025-02-20T00:00:00+00:00 [queued]>
[2025-02-22T19:38:05.473+0000] {taskinstance.py:1157} INFO - Dependencies all met for dep_context=requeueable deps ti=<TaskInstance: coingecko_ingestion_dag.store_raw_data_in_hdfs scheduled__2025-02-20T00:00:00+00:00 [queued]>
[2025-02-22T19:38:05.474+0000] {taskinstance.py:1359} INFO - Starting attempt 1 of 2
[2025-02-22T19:38:05.500+0000] {taskinstance.py:1380} INFO - Executing <Task(PythonOperator): store_raw_data_in_hdfs> on 2025-02-20 00:00:00+00:00
[2025-02-22T19:38:05.509+0000] {standard_task_runner.py:57} INFO - Started process 1524 to run task
[2025-02-22T19:38:05.516+0000] {standard_task_runner.py:84} INFO - Running: ['***', 'tasks', 'run', 'coingecko_ingestion_dag', 'store_raw_data_in_hdfs', 'scheduled__2025-02-20T00:00:00+00:00', '--job-id', '175', '--raw', '--subdir', 'DAGS_FOLDER/ingest_data.py', '--cfg-path', '/tmp/tmpl8hh772d']
[2025-02-22T19:38:05.523+0000] {standard_task_runner.py:85} INFO - Job 175: Subtask store_raw_data_in_hdfs
[2025-02-22T19:38:05.623+0000] {task_command.py:415} INFO - Running <TaskInstance: coingecko_ingestion_dag.store_raw_data_in_hdfs scheduled__2025-02-20T00:00:00+00:00 [running]> on host 972836975d47
[2025-02-22T19:38:05.781+0000] {taskinstance.py:1660} INFO - Exporting env vars: AIRFLOW_CTX_DAG_OWNER='etudiant' AIRFLOW_CTX_DAG_ID='coingecko_ingestion_dag' AIRFLOW_CTX_TASK_ID='store_raw_data_in_hdfs' AIRFLOW_CTX_EXECUTION_DATE='2025-02-20T00:00:00+00:00' AIRFLOW_CTX_TRY_NUMBER='1' AIRFLOW_CTX_DAG_RUN_ID='scheduled__2025-02-20T00:00:00+00:00'
[2025-02-22T19:38:05.839+0000] {taskinstance.py:1935} ERROR - Task failed with exception
Traceback (most recent call last):
  File "/home/airflow/.local/lib/python3.8/site-packages/airflow/operators/python.py", line 192, in execute
    return_value = self.execute_callable()
  File "/home/airflow/.local/lib/python3.8/site-packages/airflow/operators/python.py", line 209, in execute_callable
    return self.python_callable(*self.op_args, **self.op_kwargs)
  File "/opt/airflow/dags/ingest_data.py", line 48, in store_raw_data_in_hdfs
    subprocess.run(["hdfs", "dfs", "-mkdir", "-p", hdfs_dir])
  File "/usr/local/lib/python3.8/subprocess.py", line 493, in run
    with Popen(*popenargs, **kwargs) as process:
  File "/usr/local/lib/python3.8/subprocess.py", line 858, in __init__
    self._execute_child(args, executable, preexec_fn, close_fds,
  File "/usr/local/lib/python3.8/subprocess.py", line 1720, in _execute_child
    raise child_exception_type(errno_num, err_msg, err_filename)
PermissionError: [Errno 13] Permission denied: 'hdfs'
[2025-02-22T19:38:05.871+0000] {taskinstance.py:1398} INFO - Marking task as UP_FOR_RETRY. dag_id=coingecko_ingestion_dag, task_id=store_raw_data_in_hdfs, execution_date=20250220T000000, start_date=20250222T193805, end_date=20250222T193805
[2025-02-22T19:38:05.907+0000] {standard_task_runner.py:104} ERROR - Failed to execute job 175 for task store_raw_data_in_hdfs ([Errno 13] Permission denied: 'hdfs'; 1524)
[2025-02-22T19:38:05.938+0000] {local_task_job_runner.py:228} INFO - Task exited with return code 1
[2025-02-22T19:38:05.985+0000] {taskinstance.py:2776} INFO - 0 downstream tasks scheduled from follow-on schedule check
[2025-02-23T13:37:43.360+0000] {taskinstance.py:1157} INFO - Dependencies all met for dep_context=non-requeueable deps ti=<TaskInstance: coingecko_ingestion_dag.store_raw_data_in_hdfs scheduled__2025-02-20T00:00:00+00:00 [queued]>
[2025-02-23T13:37:43.377+0000] {taskinstance.py:1157} INFO - Dependencies all met for dep_context=requeueable deps ti=<TaskInstance: coingecko_ingestion_dag.store_raw_data_in_hdfs scheduled__2025-02-20T00:00:00+00:00 [queued]>
[2025-02-23T13:37:43.378+0000] {taskinstance.py:1359} INFO - Starting attempt 1 of 2
[2025-02-23T13:37:43.399+0000] {taskinstance.py:1380} INFO - Executing <Task(PythonOperator): store_raw_data_in_hdfs> on 2025-02-20 00:00:00+00:00
[2025-02-23T13:37:43.407+0000] {standard_task_runner.py:57} INFO - Started process 1546 to run task
[2025-02-23T13:37:43.413+0000] {standard_task_runner.py:84} INFO - Running: ['***', 'tasks', 'run', 'coingecko_ingestion_dag', 'store_raw_data_in_hdfs', 'scheduled__2025-02-20T00:00:00+00:00', '--job-id', '116', '--raw', '--subdir', 'DAGS_FOLDER/ingest_data.py', '--cfg-path', '/tmp/tmpro0jod8p']
[2025-02-23T13:37:43.423+0000] {standard_task_runner.py:85} INFO - Job 116: Subtask store_raw_data_in_hdfs
[2025-02-23T13:37:43.544+0000] {task_command.py:415} INFO - Running <TaskInstance: coingecko_ingestion_dag.store_raw_data_in_hdfs scheduled__2025-02-20T00:00:00+00:00 [running]> on host 49036eb7676e
[2025-02-23T13:37:43.718+0000] {taskinstance.py:1660} INFO - Exporting env vars: AIRFLOW_CTX_DAG_OWNER='etudiant' AIRFLOW_CTX_DAG_ID='coingecko_ingestion_dag' AIRFLOW_CTX_TASK_ID='store_raw_data_in_hdfs' AIRFLOW_CTX_EXECUTION_DATE='2025-02-20T00:00:00+00:00' AIRFLOW_CTX_TRY_NUMBER='1' AIRFLOW_CTX_DAG_RUN_ID='scheduled__2025-02-20T00:00:00+00:00'
[2025-02-23T13:37:43.762+0000] {taskinstance.py:1935} ERROR - Task failed with exception
Traceback (most recent call last):
  File "/home/airflow/.local/lib/python3.8/site-packages/airflow/operators/python.py", line 192, in execute
    return_value = self.execute_callable()
  File "/home/airflow/.local/lib/python3.8/site-packages/airflow/operators/python.py", line 209, in execute_callable
    return self.python_callable(*self.op_args, **self.op_kwargs)
  File "/opt/airflow/dags/ingest_data.py", line 48, in store_raw_data_in_hdfs
    subprocess.run(["hdfs", "dfs", "-mkdir", "-p", hdfs_dir])
  File "/usr/local/lib/python3.8/subprocess.py", line 493, in run
    with Popen(*popenargs, **kwargs) as process:
  File "/usr/local/lib/python3.8/subprocess.py", line 858, in __init__
    self._execute_child(args, executable, preexec_fn, close_fds,
  File "/usr/local/lib/python3.8/subprocess.py", line 1720, in _execute_child
    raise child_exception_type(errno_num, err_msg, err_filename)
PermissionError: [Errno 13] Permission denied: 'hdfs'
[2025-02-23T13:37:43.786+0000] {taskinstance.py:1398} INFO - Marking task as UP_FOR_RETRY. dag_id=coingecko_ingestion_dag, task_id=store_raw_data_in_hdfs, execution_date=20250220T000000, start_date=20250223T133743, end_date=20250223T133743
[2025-02-23T13:37:43.814+0000] {standard_task_runner.py:104} ERROR - Failed to execute job 116 for task store_raw_data_in_hdfs ([Errno 13] Permission denied: 'hdfs'; 1546)
[2025-02-23T13:37:43.870+0000] {local_task_job_runner.py:228} INFO - Task exited with return code 1
[2025-02-23T13:37:43.904+0000] {taskinstance.py:2776} INFO - 0 downstream tasks scheduled from follow-on schedule check
