[2025-02-22T19:43:07.518+0000] {taskinstance.py:1157} INFO - Dependencies all met for dep_context=non-requeueable deps ti=<TaskInstance: coingecko_ingestion_dag.store_raw_data_in_hdfs scheduled__2025-02-20T00:00:00+00:00 [queued]>
[2025-02-22T19:43:07.540+0000] {taskinstance.py:1157} INFO - Dependencies all met for dep_context=requeueable deps ti=<TaskInstance: coingecko_ingestion_dag.store_raw_data_in_hdfs scheduled__2025-02-20T00:00:00+00:00 [queued]>
[2025-02-22T19:43:07.541+0000] {taskinstance.py:1359} INFO - Starting attempt 2 of 2
[2025-02-22T19:43:07.574+0000] {taskinstance.py:1380} INFO - Executing <Task(PythonOperator): store_raw_data_in_hdfs> on 2025-02-20 00:00:00+00:00
[2025-02-22T19:43:07.583+0000] {standard_task_runner.py:57} INFO - Started process 1592 to run task
[2025-02-22T19:43:07.591+0000] {standard_task_runner.py:84} INFO - Running: ['***', 'tasks', 'run', 'coingecko_ingestion_dag', 'store_raw_data_in_hdfs', 'scheduled__2025-02-20T00:00:00+00:00', '--job-id', '184', '--raw', '--subdir', 'DAGS_FOLDER/ingest_data.py', '--cfg-path', '/tmp/tmpr800w6bj']
[2025-02-22T19:43:07.601+0000] {standard_task_runner.py:85} INFO - Job 184: Subtask store_raw_data_in_hdfs
[2025-02-22T19:43:07.740+0000] {task_command.py:415} INFO - Running <TaskInstance: coingecko_ingestion_dag.store_raw_data_in_hdfs scheduled__2025-02-20T00:00:00+00:00 [running]> on host 972836975d47
[2025-02-22T19:43:07.919+0000] {taskinstance.py:1660} INFO - Exporting env vars: AIRFLOW_CTX_DAG_OWNER='etudiant' AIRFLOW_CTX_DAG_ID='coingecko_ingestion_dag' AIRFLOW_CTX_TASK_ID='store_raw_data_in_hdfs' AIRFLOW_CTX_EXECUTION_DATE='2025-02-20T00:00:00+00:00' AIRFLOW_CTX_TRY_NUMBER='2' AIRFLOW_CTX_DAG_RUN_ID='scheduled__2025-02-20T00:00:00+00:00'
[2025-02-22T19:43:07.976+0000] {taskinstance.py:1935} ERROR - Task failed with exception
Traceback (most recent call last):
  File "/home/airflow/.local/lib/python3.8/site-packages/airflow/operators/python.py", line 192, in execute
    return_value = self.execute_callable()
  File "/home/airflow/.local/lib/python3.8/site-packages/airflow/operators/python.py", line 209, in execute_callable
    return self.python_callable(*self.op_args, **self.op_kwargs)
  File "/opt/airflow/dags/ingest_data.py", line 48, in store_raw_data_in_hdfs
    subprocess.run(["hdfs", "dfs", "-mkdir", "-p", hdfs_dir])
  File "/usr/local/lib/python3.8/subprocess.py", line 493, in run
    with Popen(*popenargs, **kwargs) as process:
  File "/usr/local/lib/python3.8/subprocess.py", line 858, in __init__
    self._execute_child(args, executable, preexec_fn, close_fds,
  File "/usr/local/lib/python3.8/subprocess.py", line 1720, in _execute_child
    raise child_exception_type(errno_num, err_msg, err_filename)
PermissionError: [Errno 13] Permission denied: 'hdfs'
[2025-02-22T19:43:08.002+0000] {taskinstance.py:1398} INFO - Marking task as FAILED. dag_id=coingecko_ingestion_dag, task_id=store_raw_data_in_hdfs, execution_date=20250220T000000, start_date=20250222T194307, end_date=20250222T194308
[2025-02-22T19:43:08.031+0000] {standard_task_runner.py:104} ERROR - Failed to execute job 184 for task store_raw_data_in_hdfs ([Errno 13] Permission denied: 'hdfs'; 1592)
[2025-02-22T19:43:08.049+0000] {local_task_job_runner.py:228} INFO - Task exited with return code 1
[2025-02-22T19:43:08.083+0000] {taskinstance.py:2776} INFO - 0 downstream tasks scheduled from follow-on schedule check
[2025-02-23T13:42:45.059+0000] {taskinstance.py:1157} INFO - Dependencies all met for dep_context=non-requeueable deps ti=<TaskInstance: coingecko_ingestion_dag.store_raw_data_in_hdfs scheduled__2025-02-20T00:00:00+00:00 [queued]>
[2025-02-23T13:42:45.075+0000] {taskinstance.py:1157} INFO - Dependencies all met for dep_context=requeueable deps ti=<TaskInstance: coingecko_ingestion_dag.store_raw_data_in_hdfs scheduled__2025-02-20T00:00:00+00:00 [queued]>
[2025-02-23T13:42:45.076+0000] {taskinstance.py:1359} INFO - Starting attempt 2 of 2
[2025-02-23T13:42:45.099+0000] {taskinstance.py:1380} INFO - Executing <Task(PythonOperator): store_raw_data_in_hdfs> on 2025-02-20 00:00:00+00:00
[2025-02-23T13:42:45.107+0000] {standard_task_runner.py:57} INFO - Started process 1630 to run task
[2025-02-23T13:42:45.114+0000] {standard_task_runner.py:84} INFO - Running: ['***', 'tasks', 'run', 'coingecko_ingestion_dag', 'store_raw_data_in_hdfs', 'scheduled__2025-02-20T00:00:00+00:00', '--job-id', '127', '--raw', '--subdir', 'DAGS_FOLDER/ingest_data.py', '--cfg-path', '/tmp/tmp5u0sna9s']
[2025-02-23T13:42:45.122+0000] {standard_task_runner.py:85} INFO - Job 127: Subtask store_raw_data_in_hdfs
[2025-02-23T13:42:45.225+0000] {task_command.py:415} INFO - Running <TaskInstance: coingecko_ingestion_dag.store_raw_data_in_hdfs scheduled__2025-02-20T00:00:00+00:00 [running]> on host 49036eb7676e
[2025-02-23T13:42:45.345+0000] {taskinstance.py:1660} INFO - Exporting env vars: AIRFLOW_CTX_DAG_OWNER='etudiant' AIRFLOW_CTX_DAG_ID='coingecko_ingestion_dag' AIRFLOW_CTX_TASK_ID='store_raw_data_in_hdfs' AIRFLOW_CTX_EXECUTION_DATE='2025-02-20T00:00:00+00:00' AIRFLOW_CTX_TRY_NUMBER='2' AIRFLOW_CTX_DAG_RUN_ID='scheduled__2025-02-20T00:00:00+00:00'
[2025-02-23T13:42:45.379+0000] {taskinstance.py:1935} ERROR - Task failed with exception
Traceback (most recent call last):
  File "/home/airflow/.local/lib/python3.8/site-packages/airflow/operators/python.py", line 192, in execute
    return_value = self.execute_callable()
  File "/home/airflow/.local/lib/python3.8/site-packages/airflow/operators/python.py", line 209, in execute_callable
    return self.python_callable(*self.op_args, **self.op_kwargs)
  File "/opt/airflow/dags/ingest_data.py", line 48, in store_raw_data_in_hdfs
    subprocess.run(["hdfs", "dfs", "-mkdir", "-p", hdfs_dir])
  File "/usr/local/lib/python3.8/subprocess.py", line 493, in run
    with Popen(*popenargs, **kwargs) as process:
  File "/usr/local/lib/python3.8/subprocess.py", line 858, in __init__
    self._execute_child(args, executable, preexec_fn, close_fds,
  File "/usr/local/lib/python3.8/subprocess.py", line 1720, in _execute_child
    raise child_exception_type(errno_num, err_msg, err_filename)
PermissionError: [Errno 13] Permission denied: 'hdfs'
[2025-02-23T13:42:45.399+0000] {taskinstance.py:1398} INFO - Marking task as FAILED. dag_id=coingecko_ingestion_dag, task_id=store_raw_data_in_hdfs, execution_date=20250220T000000, start_date=20250223T134245, end_date=20250223T134245
[2025-02-23T13:42:45.423+0000] {standard_task_runner.py:104} ERROR - Failed to execute job 127 for task store_raw_data_in_hdfs ([Errno 13] Permission denied: 'hdfs'; 1630)
[2025-02-23T13:42:45.449+0000] {local_task_job_runner.py:228} INFO - Task exited with return code 1
[2025-02-23T13:42:45.484+0000] {taskinstance.py:2776} INFO - 0 downstream tasks scheduled from follow-on schedule check
