[2025-02-22T18:47:15.354+0000] {taskinstance.py:1157} INFO - Dependencies all met for dep_context=non-requeueable deps ti=<TaskInstance: new_dag_1.check_file manual__2025-02-22T18:43:04.119246+00:00 [queued]>
[2025-02-22T18:47:15.365+0000] {taskinstance.py:1157} INFO - Dependencies all met for dep_context=requeueable deps ti=<TaskInstance: new_dag_1.check_file manual__2025-02-22T18:43:04.119246+00:00 [queued]>
[2025-02-22T18:47:15.366+0000] {taskinstance.py:1359} INFO - Starting attempt 3 of 6
[2025-02-22T18:47:15.383+0000] {taskinstance.py:1380} INFO - Executing <Task(BashOperator): check_file> on 2025-02-22 18:43:04.119246+00:00
[2025-02-22T18:47:15.389+0000] {standard_task_runner.py:57} INFO - Started process 389 to run task
[2025-02-22T18:47:15.393+0000] {standard_task_runner.py:84} INFO - Running: ['***', 'tasks', 'run', 'new_dag_1', 'check_file', 'manual__2025-02-22T18:43:04.119246+00:00', '--job-id', '13', '--raw', '--subdir', 'DAGS_FOLDER/ingest_data.py', '--cfg-path', '/tmp/tmpa2krx6kx']
[2025-02-22T18:47:15.396+0000] {standard_task_runner.py:85} INFO - Job 13: Subtask check_file
[2025-02-22T18:47:15.460+0000] {task_command.py:415} INFO - Running <TaskInstance: new_dag_1.check_file manual__2025-02-22T18:43:04.119246+00:00 [running]> on host 972836975d47
[2025-02-22T18:47:15.562+0000] {taskinstance.py:1660} INFO - Exporting env vars: AIRFLOW_CTX_DAG_OWNER='***' AIRFLOW_CTX_DAG_ID='new_dag_1' AIRFLOW_CTX_TASK_ID='check_file' AIRFLOW_CTX_EXECUTION_DATE='2025-02-22T18:43:04.119246+00:00' AIRFLOW_CTX_TRY_NUMBER='3' AIRFLOW_CTX_DAG_RUN_ID='manual__2025-02-22T18:43:04.119246+00:00'
[2025-02-22T18:47:15.565+0000] {subprocess.py:63} INFO - Tmp dir root location: /tmp
[2025-02-22T18:47:15.566+0000] {subprocess.py:75} INFO - Running command: ['/bin/bash', '-c', 'ls -l /mnt/d/projets/***/input/persons.csv']
[2025-02-22T18:47:15.578+0000] {subprocess.py:86} INFO - Output:
[2025-02-22T18:47:15.584+0000] {subprocess.py:93} INFO - ls: cannot access '/mnt/d/projets/***/input/persons.csv': No such file or directory
[2025-02-22T18:47:15.585+0000] {subprocess.py:97} INFO - Command exited with return code 2
[2025-02-22T18:47:15.601+0000] {taskinstance.py:1935} ERROR - Task failed with exception
Traceback (most recent call last):
  File "/home/airflow/.local/lib/python3.8/site-packages/airflow/operators/bash.py", line 210, in execute
    raise AirflowException(
airflow.exceptions.AirflowException: Bash command failed. The command returned a non-zero exit code 2.
[2025-02-22T18:47:15.607+0000] {taskinstance.py:1398} INFO - Marking task as UP_FOR_RETRY. dag_id=new_dag_1, task_id=check_file, execution_date=20250222T184304, start_date=20250222T184715, end_date=20250222T184715
[2025-02-22T18:47:15.629+0000] {standard_task_runner.py:104} ERROR - Failed to execute job 13 for task check_file (Bash command failed. The command returned a non-zero exit code 2.; 389)
[2025-02-22T18:47:15.646+0000] {local_task_job_runner.py:228} INFO - Task exited with return code 1
[2025-02-22T18:47:15.668+0000] {taskinstance.py:2776} INFO - 0 downstream tasks scheduled from follow-on schedule check
