[2025-02-23T17:03:43.322+0000] {taskinstance.py:1159} INFO - Dependencies all met for dep_context=non-requeueable deps ti=<TaskInstance: fetch_crypto_data_and_upload_to_hdfs.upload_to_hdfs scheduled__2025-02-22T00:00:00+00:00 [queued]>
[2025-02-23T17:03:43.334+0000] {taskinstance.py:1159} INFO - Dependencies all met for dep_context=requeueable deps ti=<TaskInstance: fetch_crypto_data_and_upload_to_hdfs.upload_to_hdfs scheduled__2025-02-22T00:00:00+00:00 [queued]>
[2025-02-23T17:03:43.334+0000] {taskinstance.py:1361} INFO - Starting attempt 2 of 2
[2025-02-23T17:03:43.349+0000] {taskinstance.py:1382} INFO - Executing <Task(BashOperator): upload_to_hdfs> on 2025-02-22 00:00:00+00:00
[2025-02-23T17:03:43.356+0000] {standard_task_runner.py:57} INFO - Started process 3900 to run task
[2025-02-23T17:03:43.360+0000] {standard_task_runner.py:84} INFO - Running: ['***', 'tasks', 'run', 'fetch_crypto_data_and_upload_to_hdfs', 'upload_to_hdfs', 'scheduled__2025-02-22T00:00:00+00:00', '--job-id', '15', '--raw', '--subdir', 'DAGS_FOLDER/ingest_data.py', '--cfg-path', '/tmp/tmpvcidl7s3']
[2025-02-23T17:03:43.364+0000] {standard_task_runner.py:85} INFO - Job 15: Subtask upload_to_hdfs
[2025-02-23T17:03:43.453+0000] {task_command.py:415} INFO - Running <TaskInstance: fetch_crypto_data_and_upload_to_hdfs.upload_to_hdfs scheduled__2025-02-22T00:00:00+00:00 [running]> on host 39872518d13d
[2025-02-23T17:03:43.581+0000] {taskinstance.py:1660} INFO - Exporting env vars: AIRFLOW_CTX_DAG_OWNER='***' AIRFLOW_CTX_DAG_ID='fetch_crypto_data_and_upload_to_hdfs' AIRFLOW_CTX_TASK_ID='upload_to_hdfs' AIRFLOW_CTX_EXECUTION_DATE='2025-02-22T00:00:00+00:00' AIRFLOW_CTX_TRY_NUMBER='2' AIRFLOW_CTX_DAG_RUN_ID='scheduled__2025-02-22T00:00:00+00:00'
[2025-02-23T17:03:43.584+0000] {subprocess.py:63} INFO - Tmp dir root location: /tmp
[2025-02-23T17:03:43.586+0000] {subprocess.py:75} INFO - Running command: ['/bin/bash', '-c', 'docker exec -it -u root namenode bash -c "hdfs dfs -put -f /tmp/crypto_historical_data.csv /user/hadoop/crypto_historical_data.csv"']
[2025-02-23T17:03:43.602+0000] {subprocess.py:86} INFO - Output:
[2025-02-23T17:03:43.652+0000] {subprocess.py:93} INFO - the input device is not a TTY
[2025-02-23T17:03:43.654+0000] {subprocess.py:97} INFO - Command exited with return code 1
[2025-02-23T17:03:43.695+0000] {taskinstance.py:1943} ERROR - Task failed with exception
Traceback (most recent call last):
  File "/home/airflow/.local/lib/python3.9/site-packages/airflow/operators/bash.py", line 210, in execute
    raise AirflowException(
airflow.exceptions.AirflowException: Bash command failed. The command returned a non-zero exit code 1.
[2025-02-23T17:03:43.712+0000] {taskinstance.py:1400} INFO - Marking task as FAILED. dag_id=fetch_crypto_data_and_upload_to_hdfs, task_id=upload_to_hdfs, execution_date=20250222T000000, start_date=20250223T170343, end_date=20250223T170343
[2025-02-23T17:03:43.736+0000] {standard_task_runner.py:104} ERROR - Failed to execute job 15 for task upload_to_hdfs (Bash command failed. The command returned a non-zero exit code 1.; 3900)
[2025-02-23T17:03:43.774+0000] {local_task_job_runner.py:228} INFO - Task exited with return code 1
[2025-02-23T17:03:43.813+0000] {taskinstance.py:2784} INFO - 0 downstream tasks scheduled from follow-on schedule check
[2025-02-23T18:09:25.863+0000] {taskinstance.py:1159} INFO - Dependencies all met for dep_context=non-requeueable deps ti=<TaskInstance: fetch_crypto_data_and_upload_to_hdfs.upload_to_hdfs scheduled__2025-02-22T00:00:00+00:00 [queued]>
[2025-02-23T18:09:25.877+0000] {taskinstance.py:1159} INFO - Dependencies all met for dep_context=requeueable deps ti=<TaskInstance: fetch_crypto_data_and_upload_to_hdfs.upload_to_hdfs scheduled__2025-02-22T00:00:00+00:00 [queued]>
[2025-02-23T18:09:25.878+0000] {taskinstance.py:1361} INFO - Starting attempt 2 of 2
[2025-02-23T18:09:25.901+0000] {taskinstance.py:1382} INFO - Executing <Task(BashOperator): upload_to_hdfs> on 2025-02-22 00:00:00+00:00
[2025-02-23T18:09:25.908+0000] {standard_task_runner.py:57} INFO - Started process 7869 to run task
[2025-02-23T18:09:25.920+0000] {standard_task_runner.py:84} INFO - Running: ['***', 'tasks', 'run', 'fetch_crypto_data_and_upload_to_hdfs', 'upload_to_hdfs', 'scheduled__2025-02-22T00:00:00+00:00', '--job-id', '8', '--raw', '--subdir', 'DAGS_FOLDER/ingest_data.py', '--cfg-path', '/tmp/tmpunez_6pt']
[2025-02-23T18:09:25.926+0000] {standard_task_runner.py:85} INFO - Job 8: Subtask upload_to_hdfs
[2025-02-23T18:09:26.039+0000] {task_command.py:415} INFO - Running <TaskInstance: fetch_crypto_data_and_upload_to_hdfs.upload_to_hdfs scheduled__2025-02-22T00:00:00+00:00 [running]> on host 95f034191b67
[2025-02-23T18:09:26.192+0000] {taskinstance.py:1660} INFO - Exporting env vars: AIRFLOW_CTX_DAG_OWNER='***' AIRFLOW_CTX_DAG_ID='fetch_crypto_data_and_upload_to_hdfs' AIRFLOW_CTX_TASK_ID='upload_to_hdfs' AIRFLOW_CTX_EXECUTION_DATE='2025-02-22T00:00:00+00:00' AIRFLOW_CTX_TRY_NUMBER='2' AIRFLOW_CTX_DAG_RUN_ID='scheduled__2025-02-22T00:00:00+00:00'
[2025-02-23T18:09:26.195+0000] {subprocess.py:63} INFO - Tmp dir root location: /tmp
[2025-02-23T18:09:26.199+0000] {subprocess.py:75} INFO - Running command: ['/bin/bash', '-c', 'cd /tmp && docker cp crypto_historical_data.csv namenode:/tmp/crypto_historical_data.csv && docker exec -it namenode bash -c "cd /tmp && hdfs dfs -put crypto_historical_data.csv"']
[2025-02-23T18:09:26.216+0000] {subprocess.py:86} INFO - Output:
[2025-02-23T18:09:26.388+0000] {subprocess.py:93} INFO - the input device is not a TTY
[2025-02-23T18:09:26.391+0000] {subprocess.py:97} INFO - Command exited with return code 1
[2025-02-23T18:09:26.418+0000] {taskinstance.py:1943} ERROR - Task failed with exception
Traceback (most recent call last):
  File "/home/airflow/.local/lib/python3.9/site-packages/airflow/operators/bash.py", line 210, in execute
    raise AirflowException(
airflow.exceptions.AirflowException: Bash command failed. The command returned a non-zero exit code 1.
[2025-02-23T18:09:26.427+0000] {taskinstance.py:1400} INFO - Marking task as FAILED. dag_id=fetch_crypto_data_and_upload_to_hdfs, task_id=upload_to_hdfs, execution_date=20250222T000000, start_date=20250223T180925, end_date=20250223T180926
[2025-02-23T18:09:26.452+0000] {standard_task_runner.py:104} ERROR - Failed to execute job 8 for task upload_to_hdfs (Bash command failed. The command returned a non-zero exit code 1.; 7869)
[2025-02-23T18:09:26.495+0000] {local_task_job_runner.py:228} INFO - Task exited with return code 1
[2025-02-23T18:09:26.567+0000] {taskinstance.py:2784} INFO - 0 downstream tasks scheduled from follow-on schedule check
