[2025-02-24T09:44:56.312+0000] {taskinstance.py:1159} INFO - Dependencies all met for dep_context=non-requeueable deps ti=<TaskInstance: fetch_crypto_data_and_upload_to_hdfs.upload_to_hdfs manual__2025-02-24T09:39:35.521677+00:00 [queued]>
[2025-02-24T09:44:56.323+0000] {taskinstance.py:1159} INFO - Dependencies all met for dep_context=requeueable deps ti=<TaskInstance: fetch_crypto_data_and_upload_to_hdfs.upload_to_hdfs manual__2025-02-24T09:39:35.521677+00:00 [queued]>
[2025-02-24T09:44:56.324+0000] {taskinstance.py:1361} INFO - Starting attempt 2 of 2
[2025-02-24T09:44:56.344+0000] {taskinstance.py:1382} INFO - Executing <Task(DockerOperator): upload_to_hdfs> on 2025-02-24 09:39:35.521677+00:00
[2025-02-24T09:44:56.353+0000] {standard_task_runner.py:57} INFO - Started process 25396 to run task
[2025-02-24T09:44:56.356+0000] {standard_task_runner.py:84} INFO - Running: ['***', 'tasks', 'run', 'fetch_crypto_data_and_upload_to_hdfs', 'upload_to_hdfs', 'manual__2025-02-24T09:39:35.521677+00:00', '--job-id', '6', '--raw', '--subdir', 'DAGS_FOLDER/ingest_data.py', '--cfg-path', '/tmp/tmpngc6qhjd']
[2025-02-24T09:44:56.360+0000] {standard_task_runner.py:85} INFO - Job 6: Subtask upload_to_hdfs
[2025-02-24T09:44:56.422+0000] {task_command.py:415} INFO - Running <TaskInstance: fetch_crypto_data_and_upload_to_hdfs.upload_to_hdfs manual__2025-02-24T09:39:35.521677+00:00 [running]> on host 781ad978c51a
[2025-02-24T09:44:56.512+0000] {taskinstance.py:1660} INFO - Exporting env vars: AIRFLOW_CTX_DAG_OWNER='***' AIRFLOW_CTX_DAG_ID='fetch_crypto_data_and_upload_to_hdfs' AIRFLOW_CTX_TASK_ID='upload_to_hdfs' AIRFLOW_CTX_EXECUTION_DATE='2025-02-24T09:39:35.521677+00:00' AIRFLOW_CTX_TRY_NUMBER='2' AIRFLOW_CTX_DAG_RUN_ID='manual__2025-02-24T09:39:35.521677+00:00'
[2025-02-24T09:44:56.544+0000] {docker.py:333} INFO - Starting docker container from image apache/***:2.7.0-python3.9
[2025-02-24T09:44:56.561+0000] {docker.py:341} WARNING - Using remote engine or docker-in-docker and mounting temporary volume from host is not supported. Falling back to `mount_tmp_dir=False` mode. You can set `mount_tmp_dir` parameter to False to disable mounting and remove the warning
[2025-02-24T09:44:56.582+0000] {taskinstance.py:1943} ERROR - Task failed with exception
Traceback (most recent call last):
  File "/home/airflow/.local/lib/python3.9/site-packages/docker/api/client.py", line 268, in _raise_for_status
    response.raise_for_status()
  File "/home/airflow/.local/lib/python3.9/site-packages/requests/models.py", line 1021, in raise_for_status
    raise HTTPError(http_error_msg, response=self)
requests.exceptions.HTTPError: 400 Client Error: Bad Request for url: http+docker://localhost/v1.47/containers/create?name=namenode

The above exception was the direct cause of the following exception:

Traceback (most recent call last):
  File "/home/airflow/.local/lib/python3.9/site-packages/airflow/providers/docker/operators/docker.py", line 338, in _run_image
    return self._run_image_with_mounts(self.mounts + [tmp_mount], add_tmp_variable=True)
  File "/home/airflow/.local/lib/python3.9/site-packages/airflow/providers/docker/operators/docker.py", line 365, in _run_image_with_mounts
    self.container = self.cli.create_container(
  File "/home/airflow/.local/lib/python3.9/site-packages/docker/api/container.py", line 431, in create_container
    return self.create_container_from_config(config, name, platform)
  File "/home/airflow/.local/lib/python3.9/site-packages/docker/api/container.py", line 448, in create_container_from_config
    return self._result(res, True)
  File "/home/airflow/.local/lib/python3.9/site-packages/docker/api/client.py", line 274, in _result
    self._raise_for_status(response)
  File "/home/airflow/.local/lib/python3.9/site-packages/docker/api/client.py", line 270, in _raise_for_status
    raise create_api_error_from_http_exception(e) from e
  File "/home/airflow/.local/lib/python3.9/site-packages/docker/errors.py", line 39, in create_api_error_from_http_exception
    raise cls(e, response=response, explanation=explanation) from e
docker.errors.APIError: 400 Client Error for http+docker://localhost/v1.47/containers/create?name=namenode: Bad Request ("invalid mount config for type "bind": bind source path does not exist: /tmp/airflowtmp4krtcgee")

During handling of the above exception, another exception occurred:

Traceback (most recent call last):
  File "/home/airflow/.local/lib/python3.9/site-packages/docker/api/client.py", line 268, in _raise_for_status
    response.raise_for_status()
  File "/home/airflow/.local/lib/python3.9/site-packages/requests/models.py", line 1021, in raise_for_status
    raise HTTPError(http_error_msg, response=self)
requests.exceptions.HTTPError: 409 Client Error: Conflict for url: http+docker://localhost/v1.47/containers/create?name=namenode

The above exception was the direct cause of the following exception:

Traceback (most recent call last):
  File "/home/airflow/.local/lib/python3.9/site-packages/airflow/providers/docker/operators/docker.py", line 476, in execute
    return self._run_image()
  File "/home/airflow/.local/lib/python3.9/site-packages/airflow/providers/docker/operators/docker.py", line 347, in _run_image
    return self._run_image_with_mounts(self.mounts, add_tmp_variable=False)
  File "/home/airflow/.local/lib/python3.9/site-packages/airflow/providers/docker/operators/docker.py", line 365, in _run_image_with_mounts
    self.container = self.cli.create_container(
  File "/home/airflow/.local/lib/python3.9/site-packages/docker/api/container.py", line 431, in create_container
    return self.create_container_from_config(config, name, platform)
  File "/home/airflow/.local/lib/python3.9/site-packages/docker/api/container.py", line 448, in create_container_from_config
    return self._result(res, True)
  File "/home/airflow/.local/lib/python3.9/site-packages/docker/api/client.py", line 274, in _result
    self._raise_for_status(response)
  File "/home/airflow/.local/lib/python3.9/site-packages/docker/api/client.py", line 270, in _raise_for_status
    raise create_api_error_from_http_exception(e) from e
  File "/home/airflow/.local/lib/python3.9/site-packages/docker/errors.py", line 39, in create_api_error_from_http_exception
    raise cls(e, response=response, explanation=explanation) from e
docker.errors.APIError: 409 Client Error for http+docker://localhost/v1.47/containers/create?name=namenode: Conflict ("Conflict. The container name "/namenode" is already in use by container "0f1931b12c1516b541dea3916ae80085c3e288366b60304f2d69236e273c8d59". You have to remove (or rename) that container to be able to reuse that name.")
[2025-02-24T09:44:56.597+0000] {taskinstance.py:1400} INFO - Marking task as FAILED. dag_id=fetch_crypto_data_and_upload_to_hdfs, task_id=upload_to_hdfs, execution_date=20250224T093935, start_date=20250224T094456, end_date=20250224T094456
[2025-02-24T09:44:56.614+0000] {standard_task_runner.py:104} ERROR - Failed to execute job 6 for task upload_to_hdfs (409 Client Error for http+docker://localhost/v1.47/containers/create?name=namenode: Conflict ("Conflict. The container name "/namenode" is already in use by container "0f1931b12c1516b541dea3916ae80085c3e288366b60304f2d69236e273c8d59". You have to remove (or rename) that container to be able to reuse that name."); 25396)
[2025-02-24T09:44:56.650+0000] {local_task_job_runner.py:228} INFO - Task exited with return code 1
[2025-02-24T09:44:56.679+0000] {taskinstance.py:2784} INFO - 0 downstream tasks scheduled from follow-on schedule check
