[2025-02-23T20:06:53.802+0000] {taskinstance.py:1159} INFO - Dependencies all met for dep_context=non-requeueable deps ti=<TaskInstance: fetch_crypto_data_and_upload_to_hdfs.upload_to_hdfs manual__2025-02-23T20:01:40.215498+00:00 [queued]>
[2025-02-23T20:06:53.812+0000] {taskinstance.py:1159} INFO - Dependencies all met for dep_context=requeueable deps ti=<TaskInstance: fetch_crypto_data_and_upload_to_hdfs.upload_to_hdfs manual__2025-02-23T20:01:40.215498+00:00 [queued]>
[2025-02-23T20:06:53.813+0000] {taskinstance.py:1361} INFO - Starting attempt 2 of 2
[2025-02-23T20:06:53.828+0000] {taskinstance.py:1382} INFO - Executing <Task(BashOperator): upload_to_hdfs> on 2025-02-23 20:01:40.215498+00:00
[2025-02-23T20:06:53.838+0000] {standard_task_runner.py:57} INFO - Started process 36546 to run task
[2025-02-23T20:06:53.842+0000] {standard_task_runner.py:84} INFO - Running: ['***', 'tasks', 'run', 'fetch_crypto_data_and_upload_to_hdfs', 'upload_to_hdfs', 'manual__2025-02-23T20:01:40.215498+00:00', '--job-id', '42', '--raw', '--subdir', 'DAGS_FOLDER/ingest_data.py', '--cfg-path', '/tmp/tmpxdw2u9yc']
[2025-02-23T20:06:53.847+0000] {standard_task_runner.py:85} INFO - Job 42: Subtask upload_to_hdfs
[2025-02-23T20:06:53.913+0000] {task_command.py:415} INFO - Running <TaskInstance: fetch_crypto_data_and_upload_to_hdfs.upload_to_hdfs manual__2025-02-23T20:01:40.215498+00:00 [running]> on host 95f034191b67
[2025-02-23T20:06:54.007+0000] {taskinstance.py:1660} INFO - Exporting env vars: AIRFLOW_CTX_DAG_OWNER='***' AIRFLOW_CTX_DAG_ID='fetch_crypto_data_and_upload_to_hdfs' AIRFLOW_CTX_TASK_ID='upload_to_hdfs' AIRFLOW_CTX_EXECUTION_DATE='2025-02-23T20:01:40.215498+00:00' AIRFLOW_CTX_TRY_NUMBER='2' AIRFLOW_CTX_DAG_RUN_ID='manual__2025-02-23T20:01:40.215498+00:00'
[2025-02-23T20:06:54.009+0000] {subprocess.py:63} INFO - Tmp dir root location: /tmp
[2025-02-23T20:06:54.013+0000] {subprocess.py:75} INFO - Running command: ['/bin/bash', '-c', 'docker cp /tmp/crypto_historical_data.csv namenode:/tmp/crypto_historical_data.csv && docker exec -u root namenode bash -c "hdfs dfs -put -f /tmp/crypto_historical_data.csv /user/hadoop/crypto_historical_data.csv"']
[2025-02-23T20:06:54.028+0000] {subprocess.py:86} INFO - Output:
[2025-02-23T20:06:55.672+0000] {subprocess.py:93} INFO - put: `/user/hadoop/crypto_historical_data.csv': No such file or directory: `hdfs://namenode:9000/user/hadoop/crypto_historical_data.csv'
[2025-02-23T20:06:56.148+0000] {subprocess.py:97} INFO - Command exited with return code 1
[2025-02-23T20:06:56.166+0000] {taskinstance.py:1943} ERROR - Task failed with exception
Traceback (most recent call last):
  File "/home/airflow/.local/lib/python3.9/site-packages/airflow/operators/bash.py", line 210, in execute
    raise AirflowException(
airflow.exceptions.AirflowException: Bash command failed. The command returned a non-zero exit code 1.
[2025-02-23T20:06:56.171+0000] {taskinstance.py:1400} INFO - Marking task as FAILED. dag_id=fetch_crypto_data_and_upload_to_hdfs, task_id=upload_to_hdfs, execution_date=20250223T200140, start_date=20250223T200653, end_date=20250223T200656
[2025-02-23T20:06:56.187+0000] {standard_task_runner.py:104} ERROR - Failed to execute job 42 for task upload_to_hdfs (Bash command failed. The command returned a non-zero exit code 1.; 36546)
[2025-02-23T20:06:56.205+0000] {local_task_job_runner.py:228} INFO - Task exited with return code 1
[2025-02-23T20:06:56.230+0000] {taskinstance.py:2784} INFO - 0 downstream tasks scheduled from follow-on schedule check
