[2025-02-25T16:21:38.603+0000] {taskinstance.py:1159} INFO - Dependencies all met for dep_context=non-requeueable deps ti=<TaskInstance: crypto_data_processing_mapreduce.run_mapreduce_job manual__2025-02-25T16:21:33.494421+00:00 [queued]>
[2025-02-25T16:21:38.614+0000] {taskinstance.py:1159} INFO - Dependencies all met for dep_context=requeueable deps ti=<TaskInstance: crypto_data_processing_mapreduce.run_mapreduce_job manual__2025-02-25T16:21:33.494421+00:00 [queued]>
[2025-02-25T16:21:38.615+0000] {taskinstance.py:1361} INFO - Starting attempt 1 of 2
[2025-02-25T16:21:38.641+0000] {taskinstance.py:1382} INFO - Executing <Task(BashOperator): run_mapreduce_job> on 2025-02-25 16:21:33.494421+00:00
[2025-02-25T16:21:38.650+0000] {standard_task_runner.py:57} INFO - Started process 52324 to run task
[2025-02-25T16:21:38.658+0000] {standard_task_runner.py:84} INFO - Running: ['***', 'tasks', 'run', 'crypto_data_processing_mapreduce', 'run_mapreduce_job', 'manual__2025-02-25T16:21:33.494421+00:00', '--job-id', '8', '--raw', '--subdir', 'DAGS_FOLDER/transform_data.py', '--cfg-path', '/tmp/tmptcsgapqh']
[2025-02-25T16:21:38.663+0000] {standard_task_runner.py:85} INFO - Job 8: Subtask run_mapreduce_job
[2025-02-25T16:21:38.794+0000] {task_command.py:415} INFO - Running <TaskInstance: crypto_data_processing_mapreduce.run_mapreduce_job manual__2025-02-25T16:21:33.494421+00:00 [running]> on host 53d736af5afa
[2025-02-25T16:21:38.886+0000] {logging_mixin.py:151} WARNING - /home/***/.local/lib/python3.9/site-packages/***/utils/context.py:206 AirflowContextDeprecationWarning: Accessing 'execution_date' from the template is deprecated and will be removed in a future version. Please use 'data_interval_start' or 'logical_date' instead.
[2025-02-25T16:21:38.937+0000] {taskinstance.py:1660} INFO - Exporting env vars: AIRFLOW_CTX_DAG_OWNER='***' AIRFLOW_CTX_DAG_ID='crypto_data_processing_mapreduce' AIRFLOW_CTX_TASK_ID='run_mapreduce_job' AIRFLOW_CTX_EXECUTION_DATE='2025-02-25T16:21:33.494421+00:00' AIRFLOW_CTX_TRY_NUMBER='1' AIRFLOW_CTX_DAG_RUN_ID='manual__2025-02-25T16:21:33.494421+00:00'
[2025-02-25T16:21:38.940+0000] {subprocess.py:63} INFO - Tmp dir root location: /tmp
[2025-02-25T16:21:38.943+0000] {subprocess.py:75} INFO - Running command: ['/bin/bash', '-c', '\n        docker exec namenode hadoop jar /opt/hadoop-3.2.1/share/hadoop/tools/lib/hadoop-streaming-3.2.1.jar           -input /user/root/crypto/YYYY=2025/MM=02/DD=25/crypto_historical_data.csv           -output /user/root/crypto/processed/YYYY=2025/MM=02/DD=25           -mapper /home/mapper.py           -reducer /home/reducer.py           -file /home/mapper.py           -file /home/reducer.py\n        ']
[2025-02-25T16:21:38.953+0000] {subprocess.py:86} INFO - Output:
[2025-02-25T16:21:38.961+0000] {subprocess.py:93} INFO - /bin/bash: line 2: docker: command not found
[2025-02-25T16:21:38.962+0000] {subprocess.py:97} INFO - Command exited with return code 127
[2025-02-25T16:21:38.982+0000] {taskinstance.py:1943} ERROR - Task failed with exception
Traceback (most recent call last):
  File "/home/airflow/.local/lib/python3.9/site-packages/airflow/operators/bash.py", line 210, in execute
    raise AirflowException(
airflow.exceptions.AirflowException: Bash command failed. The command returned a non-zero exit code 127.
[2025-02-25T16:21:38.986+0000] {taskinstance.py:1400} INFO - Marking task as UP_FOR_RETRY. dag_id=crypto_data_processing_mapreduce, task_id=run_mapreduce_job, execution_date=20250225T162133, start_date=20250225T162138, end_date=20250225T162138
[2025-02-25T16:21:39.007+0000] {standard_task_runner.py:104} ERROR - Failed to execute job 8 for task run_mapreduce_job (Bash command failed. The command returned a non-zero exit code 127.; 52324)
[2025-02-25T16:21:39.032+0000] {local_task_job_runner.py:228} INFO - Task exited with return code 1
[2025-02-25T16:21:39.064+0000] {taskinstance.py:2784} INFO - 0 downstream tasks scheduled from follow-on schedule check
