[2025-02-27T15:30:57.428+0000] {taskinstance.py:1159} INFO - Dependencies all met for dep_context=non-requeueable deps ti=<TaskInstance: load_to_hbase.load_into_hbase manual__2025-02-27T15:30:55.400805+00:00 [queued]>
[2025-02-27T15:30:57.440+0000] {taskinstance.py:1159} INFO - Dependencies all met for dep_context=requeueable deps ti=<TaskInstance: load_to_hbase.load_into_hbase manual__2025-02-27T15:30:55.400805+00:00 [queued]>
[2025-02-27T15:30:57.440+0000] {taskinstance.py:1361} INFO - Starting attempt 1 of 2
[2025-02-27T15:30:57.456+0000] {taskinstance.py:1382} INFO - Executing <Task(PythonOperator): load_into_hbase> on 2025-02-27 15:30:55.400805+00:00
[2025-02-27T15:30:57.462+0000] {standard_task_runner.py:57} INFO - Started process 3998 to run task
[2025-02-27T15:30:57.465+0000] {standard_task_runner.py:84} INFO - Running: ['***', 'tasks', 'run', 'load_to_hbase', 'load_into_hbase', 'manual__2025-02-27T15:30:55.400805+00:00', '--job-id', '19', '--raw', '--subdir', 'DAGS_FOLDER/load_data.py', '--cfg-path', '/tmp/tmphgh0ctl1']
[2025-02-27T15:30:57.469+0000] {standard_task_runner.py:85} INFO - Job 19: Subtask load_into_hbase
[2025-02-27T15:30:57.530+0000] {task_command.py:415} INFO - Running <TaskInstance: load_to_hbase.load_into_hbase manual__2025-02-27T15:30:55.400805+00:00 [running]> on host b0117377cc2b
[2025-02-27T15:30:57.633+0000] {taskinstance.py:1660} INFO - Exporting env vars: AIRFLOW_CTX_DAG_OWNER='***' AIRFLOW_CTX_DAG_ID='load_to_hbase' AIRFLOW_CTX_TASK_ID='load_into_hbase' AIRFLOW_CTX_EXECUTION_DATE='2025-02-27T15:30:55.400805+00:00' AIRFLOW_CTX_TRY_NUMBER='1' AIRFLOW_CTX_DAG_RUN_ID='manual__2025-02-27T15:30:55.400805+00:00'
[2025-02-27T15:31:00.325+0000] {logging_mixin.py:151} INFO - Creating table 'crypto_prices'
[2025-02-27T15:49:40.855+0000] {taskinstance.py:1943} ERROR - Task failed with exception
Traceback (most recent call last):
  File "/opt/airflow/dags/load_data.py", line 50, in load_processed_data
    connection.create_table(
  File "/home/airflow/.local/lib/python3.9/site-packages/happybase/connection.py", line 309, in create_table
    self.client.createTable(name, column_descriptors)
  File "/home/airflow/.local/lib/python3.9/site-packages/thriftpy2/thrift.py", line 214, in _req
    return self._recv(_api)
  File "/home/airflow/.local/lib/python3.9/site-packages/thriftpy2/thrift.py", line 248, in _recv
    raise v
Hbase_thrift.IOError: IOError(message=b'org.apache.hadoop.hbase.DoNotRetryIOException: hconnection-0x195d662 closed\n\tat org.apache.hadoop.hbase.client.ConnectionImplementation.checkClosed(ConnectionImplementation.java:566)\n\tat org.apache.hadoop.hbase.client.ConnectionImplementation.locateRegion(ConnectionImplementation.java:747)\n\tat org.apache.hadoop.hbase.client.ConnectionImplementation.locateRegion(ConnectionImplementation.java:741)\n\tat org.apache.hadoop.hbase.client.ConnectionImplementation.locateRegion(ConnectionImplementation.java:712)\n\tat org.apache.hadoop.hbase.client.ConnectionImplementation.getRegionLocation(ConnectionImplementation.java:594)\n\tat org.apache.hadoop.hbase.client.HRegionLocator.getRegionLocation(HRegionLocator.java:72)\n\tat org.apache.hadoop.hbase.client.RegionServerCallable.prepare(RegionServerCallable.java:223)\n\tat org.apache.hadoop.hbase.client.RpcRetryingCallerImpl.callWithRetries(RpcRetryingCallerImpl.java:105)\n\tat org.apache.hadoop.hbase.client.HTable.get(HTable.java:386)\n\tat org.apache.hadoop.hbase.client.HTable.get(HTable.java:360)\n\tat org.apache.hadoop.hbase.MetaTableAccessor.getTableState(MetaTableAccessor.java:1078)\n\tat org.apache.hadoop.hbase.MetaTableAccessor.tableExists(MetaTableAccessor.java:403)\n\tat org.apache.hadoop.hbase.client.HBaseAdmin$6.rpcCall(HBaseAdmin.java:450)\n\tat org.apache.hadoop.hbase.client.HBaseAdmin$6.rpcCall(HBaseAdmin.java:447)\n\tat org.apache.hadoop.hbase.client.RpcRetryingCallable.call(RpcRetryingCallable.java:58)\n\tat org.apache.hadoop.hbase.client.RpcRetryingCallerImpl.callWithRetries(RpcRetryingCallerImpl.java:107)\n\tat org.apache.hadoop.hbase.client.HBaseAdmin.executeCallable(HBaseAdmin.java:3089)\n\tat org.apache.hadoop.hbase.client.HBaseAdmin.executeCallable(HBaseAdmin.java:3081)\n\tat org.apache.hadoop.hbase.client.HBaseAdmin.tableExists(HBaseAdmin.java:447)\n\tat org.apache.hadoop.hbase.thrift.ThriftServerRunner$HBaseHandler.createTable(ThriftServerRunner.java:1296)\n\tat sun.reflect.NativeMethodAccessorImpl.invoke0(Native Method)\n\tat sun.reflect.NativeMethodAccessorImpl.invoke(NativeMethodAccessorImpl.java:62)\n\tat sun.reflect.DelegatingMethodAccessorImpl.invoke(DelegatingMethodAccessorImpl.java:43)\n\tat java.lang.reflect.Method.invoke(Method.java:498)\n\tat org.apache.hadoop.hbase.thrift.HbaseHandlerMetricsProxy.invoke(HbaseHandlerMetricsProxy.java:66)\n\tat com.sun.proxy.$Proxy10.createTable(Unknown Source)\n\tat org.apache.hadoop.hbase.thrift.generated.Hbase$Processor$createTable.getResult(Hbase.java:3958)\n\tat org.apache.hadoop.hbase.thrift.generated.Hbase$Processor$createTable.getResult(Hbase.java:3937)\n\tat org.apache.thrift.ProcessFunction.process(ProcessFunction.java:38)\n\tat org.apache.thrift.TBaseProcessor.process(TBaseProcessor.java:39)\n\tat org.apache.hadoop.hbase.thrift.TBoundedThreadPoolServer$ClientConnnection.run(TBoundedThreadPoolServer.java:293)\n\tat java.util.concurrent.ThreadPoolExecutor.runWorker(ThreadPoolExecutor.java:1149)\n\tat java.util.concurrent.ThreadPoolExecutor$Worker.run(ThreadPoolExecutor.java:624)\n\tat java.lang.Thread.run(Thread.java:748)\n')

During handling of the above exception, another exception occurred:

Traceback (most recent call last):
  File "/home/airflow/.local/lib/python3.9/site-packages/airflow/operators/python.py", line 192, in execute
    return_value = self.execute_callable()
  File "/home/airflow/.local/lib/python3.9/site-packages/airflow/operators/python.py", line 209, in execute_callable
    return self.python_callable(*self.op_args, **self.op_kwargs)
  File "/opt/airflow/dags/load_data.py", line 80, in load_processed_data
    raise AirflowException(f"Failed to load data into HBase: {str(e)}")
airflow.exceptions.AirflowException: Failed to load data into HBase: IOError(message=b'org.apache.hadoop.hbase.DoNotRetryIOException: hconnection-0x195d662 closed\n\tat org.apache.hadoop.hbase.client.ConnectionImplementation.checkClosed(ConnectionImplementation.java:566)\n\tat org.apache.hadoop.hbase.client.ConnectionImplementation.locateRegion(ConnectionImplementation.java:747)\n\tat org.apache.hadoop.hbase.client.ConnectionImplementation.locateRegion(ConnectionImplementation.java:741)\n\tat org.apache.hadoop.hbase.client.ConnectionImplementation.locateRegion(ConnectionImplementation.java:712)\n\tat org.apache.hadoop.hbase.client.ConnectionImplementation.getRegionLocation(ConnectionImplementation.java:594)\n\tat org.apache.hadoop.hbase.client.HRegionLocator.getRegionLocation(HRegionLocator.java:72)\n\tat org.apache.hadoop.hbase.client.RegionServerCallable.prepare(RegionServerCallable.java:223)\n\tat org.apache.hadoop.hbase.client.RpcRetryingCallerImpl.callWithRetries(RpcRetryingCallerImpl.java:105)\n\tat org.apache.hadoop.hbase.client.HTable.get(HTable.java:386)\n\tat org.apache.hadoop.hbase.client.HTable.get(HTable.java:360)\n\tat org.apache.hadoop.hbase.MetaTableAccessor.getTableState(MetaTableAccessor.java:1078)\n\tat org.apache.hadoop.hbase.MetaTableAccessor.tableExists(MetaTableAccessor.java:403)\n\tat org.apache.hadoop.hbase.client.HBaseAdmin$6.rpcCall(HBaseAdmin.java:450)\n\tat org.apache.hadoop.hbase.client.HBaseAdmin$6.rpcCall(HBaseAdmin.java:447)\n\tat org.apache.hadoop.hbase.client.RpcRetryingCallable.call(RpcRetryingCallable.java:58)\n\tat org.apache.hadoop.hbase.client.RpcRetryingCallerImpl.callWithRetries(RpcRetryingCallerImpl.java:107)\n\tat org.apache.hadoop.hbase.client.HBaseAdmin.executeCallable(HBaseAdmin.java:3089)\n\tat org.apache.hadoop.hbase.client.HBaseAdmin.executeCallable(HBaseAdmin.java:3081)\n\tat org.apache.hadoop.hbase.client.HBaseAdmin.tableExists(HBaseAdmin.java:447)\n\tat org.apache.hadoop.hbase.thrift.ThriftServerRunner$HBaseHandler.createTable(ThriftServerRunner.java:1296)\n\tat sun.reflect.NativeMethodAccessorImpl.invoke0(Native Method)\n\tat sun.reflect.NativeMethodAccessorImpl.invoke(NativeMethodAccessorImpl.java:62)\n\tat sun.reflect.DelegatingMethodAccessorImpl.invoke(DelegatingMethodAccessorImpl.java:43)\n\tat java.lang.reflect.Method.invoke(Method.java:498)\n\tat org.apache.hadoop.hbase.thrift.HbaseHandlerMetricsProxy.invoke(HbaseHandlerMetricsProxy.java:66)\n\tat com.sun.proxy.$Proxy10.createTable(Unknown Source)\n\tat org.apache.hadoop.hbase.thrift.generated.Hbase$Processor$createTable.getResult(Hbase.java:3958)\n\tat org.apache.hadoop.hbase.thrift.generated.Hbase$Processor$createTable.getResult(Hbase.java:3937)\n\tat org.apache.thrift.ProcessFunction.process(ProcessFunction.java:38)\n\tat org.apache.thrift.TBaseProcessor.process(TBaseProcessor.java:39)\n\tat org.apache.hadoop.hbase.thrift.TBoundedThreadPoolServer$ClientConnnection.run(TBoundedThreadPoolServer.java:293)\n\tat java.util.concurrent.ThreadPoolExecutor.runWorker(ThreadPoolExecutor.java:1149)\n\tat java.util.concurrent.ThreadPoolExecutor$Worker.run(ThreadPoolExecutor.java:624)\n\tat java.lang.Thread.run(Thread.java:748)\n')
[2025-02-27T15:49:40.873+0000] {taskinstance.py:1400} INFO - Marking task as FAILED. dag_id=load_to_hbase, task_id=load_into_hbase, execution_date=20250227T153055, start_date=20250227T153057, end_date=20250227T154940
[2025-02-27T15:49:40.891+0000] {standard_task_runner.py:104} ERROR - Failed to execute job 19 for task load_into_hbase (Failed to load data into HBase: IOError(message=b'org.apache.hadoop.hbase.DoNotRetryIOException: hconnection-0x195d662 closed\n\tat org.apache.hadoop.hbase.client.ConnectionImplementation.checkClosed(ConnectionImplementation.java:566)\n\tat org.apache.hadoop.hbase.client.ConnectionImplementation.locateRegion(ConnectionImplementation.java:747)\n\tat org.apache.hadoop.hbase.client.ConnectionImplementation.locateRegion(ConnectionImplementation.java:741)\n\tat org.apache.hadoop.hbase.client.ConnectionImplementation.locateRegion(ConnectionImplementation.java:712)\n\tat org.apache.hadoop.hbase.client.ConnectionImplementation.getRegionLocation(ConnectionImplementation.java:594)\n\tat org.apache.hadoop.hbase.client.HRegionLocator.getRegionLocation(HRegionLocator.java:72)\n\tat org.apache.hadoop.hbase.client.RegionServerCallable.prepare(RegionServerCallable.java:223)\n\tat org.apache.hadoop.hbase.client.RpcRetryingCallerImpl.callWithRetries(RpcRetryingCallerImpl.java:105)\n\tat org.apache.hadoop.hbase.client.HTable.get(HTable.java:386)\n\tat org.apache.hadoop.hbase.client.HTable.get(HTable.java:360)\n\tat org.apache.hadoop.hbase.MetaTableAccessor.getTableState(MetaTableAccessor.java:1078)\n\tat org.apache.hadoop.hbase.MetaTableAccessor.tableExists(MetaTableAccessor.java:403)\n\tat org.apache.hadoop.hbase.client.HBaseAdmin$6.rpcCall(HBaseAdmin.java:450)\n\tat org.apache.hadoop.hbase.client.HBaseAdmin$6.rpcCall(HBaseAdmin.java:447)\n\tat org.apache.hadoop.hbase.client.RpcRetryingCallable.call(RpcRetryingCallable.java:58)\n\tat org.apache.hadoop.hbase.client.RpcRetryingCallerImpl.callWithRetries(RpcRetryingCallerImpl.java:107)\n\tat org.apache.hadoop.hbase.client.HBaseAdmin.executeCallable(HBaseAdmin.java:3089)\n\tat org.apache.hadoop.hbase.client.HBaseAdmin.executeCallable(HBaseAdmin.java:3081)\n\tat org.apache.hadoop.hbase.client.HBaseAdmin.tableExists(HBaseAdmin.java:447)\n\tat org.apache.hadoop.hbase.thrift.ThriftServerRunner$HBaseHandler.createTable(ThriftServerRunner.java:1296)\n\tat sun.reflect.NativeMethodAccessorImpl.invoke0(Native Method)\n\tat sun.reflect.NativeMethodAccessorImpl.invoke(NativeMethodAccessorImpl.java:62)\n\tat sun.reflect.DelegatingMethodAccessorImpl.invoke(DelegatingMethodAccessorImpl.java:43)\n\tat java.lang.reflect.Method.invoke(Method.java:498)\n\tat org.apache.hadoop.hbase.thrift.HbaseHandlerMetricsProxy.invoke(HbaseHandlerMetricsProxy.java:66)\n\tat com.sun.proxy.$Proxy10.createTable(Unknown Source)\n\tat org.apache.hadoop.hbase.thrift.generated.Hbase$Processor$createTable.getResult(Hbase.java:3958)\n\tat org.apache.hadoop.hbase.thrift.generated.Hbase$Processor$createTable.getResult(Hbase.java:3937)\n\tat org.apache.thrift.ProcessFunction.process(ProcessFunction.java:38)\n\tat org.apache.thrift.TBaseProcessor.process(TBaseProcessor.java:39)\n\tat org.apache.hadoop.hbase.thrift.TBoundedThreadPoolServer$ClientConnnection.run(TBoundedThreadPoolServer.java:293)\n\tat java.util.concurrent.ThreadPoolExecutor.runWorker(ThreadPoolExecutor.java:1149)\n\tat java.util.concurrent.ThreadPoolExecutor$Worker.run(ThreadPoolExecutor.java:624)\n\tat java.lang.Thread.run(Thread.java:748)\n'); 3998)
[2025-02-27T15:49:40.937+0000] {local_task_job_runner.py:228} INFO - Task exited with return code 1
[2025-02-27T15:49:40.957+0000] {taskinstance.py:2784} INFO - 0 downstream tasks scheduled from follow-on schedule check
